Workbook

Sheet Config
A1: Equipment Types | B1: Detector Types | C1: Procedure IDs | E1: Tolerance Table | I1: Technicians | J1: Reviewers | K1: Approvers | M1: Cert Number Prefix
A2: Spectrometer | B2: Survey Probe | C2: WC-CAL-001 Spectrometer Calibration | E2: Parameter | F2: Unit | G2: Tolerance (+/-) | I2: Tech 1 | J2: Reviewer 1 | K2: Approver 1 | M2: WC-ARC-CAL-
A3: Particle Counter | B3: Inclinometer | C3: WC-CAL-002 Particle Counter Calibration | E3: Detector Response | F3: % | G3: 2 | I3: Tech 2 | J3: Reviewer 2 | K3: Approver 2 | M3: Next Sequence
A4: Viscometer | B4: Gyroscope | C4: WC-CAL-003 Viscometer Calibration | E4: Inclinometer | F4: degrees | G4: 0.5 | I4: Tech 3 | M4: 1
A5: Moisture Analyser | B5: Magnetometer | C5: WC-CAL-004 Detector Calibration | E5: Gyroscope | F5: degrees | G5: 1
A6: Ferrograph | B6: Accelerometer | C6: WC-CAL-005 Inclinometer Calibration | E6: Temperature | F6: °C | G6: 2
A7: Titrator | B7: N/A | C7: WC-CAL-006 Gyroscope Calibration | E7: Humidity | F7: %RH | G7: 5
A8: pH Meter | C8: WC-CAL-007 General Instrument Calibration | E8: Voltage | F8: V | G8: 0.05
A9: Conductivity Meter | E9: Current | F9: mA | G9: 0.01
A10: Other

Sheet Certificate_Input
B2: WEARCHECK ARC — CALIBRATION CERTIFICATE INPUT
B3: Complete all fields below. Yellow cells require input.
B5: CERTIFICATE INFORMATION
B6: Certificate Number | C6: =Config!M2&TEXT(Config!M4,"0000")
B7: Date of Issue
B8: Calibration Date
B9: Next Calibration Due
B10: Calibration Procedure
B12: EQUIPMENT UNDER TEST (EUT)
B13: Equipment Name
B14: Manufacturer
B15: Model Number
B16: Serial Number
B17: Asset Number
B18: Location / Department
B20: SPECIFICATIONS & TOLERANCES
... B43: AUTHORISATION — CALIBRATED BY (TECHNICIAN)
B44: Tech Name | E44: Tech Surname
B45: Tech Title | E45: Tech Date Signed
B46: Tech Signature
B48: AUTHORISATION — REVIEWED BY
B49: Reviewer Name | E49: Reviewer Surname
B50: Reviewer Title | E50: Reviewer Date Signed
B51: Reviewer Signature
B53: AUTHORISATION — APPROVED BY
B54: Approver Name | E54: Approver Surname
B55: Approver Title | E55: Approver Date Signed
B56: Approver Signature
B58: TRACEABILITY & UNCERTAINTY
B59: Traceability: The measurements reported herein are traceable to national/international standards through an unbroken chain of calibrations. Reference standards used are documented in the Reference_Standards sheet.
B60: Uncertainty: The reported expanded uncertainty is based on a standard uncertainty multiplied by a coverage factor k=2, providing a level of confidence of approximately 95%. The uncertainty evaluation is in accordance with the Guide to the Expression of Uncertainty in Measurement (GUM).
B62: RESULTS SUMMARY (AUTO-CALCULATED)
B63: Pre-Calibration Result | C63: =IF(Calibration_Data!H3="","N/A",Calibration_Data!H3)
B64: Post-Calibration Result | C64: =IF(Calibration_Data!H21="","N/A",Calibration_Data!H21)
B65: Inclinometer Result | C65: =IF(Calibration_Data!H39="","N/A",Calibration_Data!H39)
B66: Gyroscope Result | C66: =IF(Calibration_Data!H57="","N/A",Calibration_Data!H57)
B67: OVERALL RESULT | C67: =IF(COUNTIF(C63:C66,"FAIL")>0,"FAIL",IF(COUNTIF(C63:C66,"PASS")>0,"PASS","N/A"))

Sheet Calibration_Data
B1: TABLE 1: BEFORE CALIBRATION — DETECTOR RESPONSE
B2: # | C2: Set Point | D2: Actual Reading | E2: Deviation | F2: Tolerance (+/-) | G2: Conformance | H2: Section Result
B3: 1 | E3: =IF(AND(C3<>"",D3<>""),D3-C3,"") | F3: =IF(C3<>"",Certificate_Input!C21,"") | G3: =IF(E3="","",IF(ABS(E3)<=F3,"PASS","FAIL")) | H3: =IF(COUNTBLANK(G3:G17)=15,"",IF(COUNTIF(G3:G17,"FAIL")>0,"FAIL","PASS"))
B4: 2 | E4: =IF(AND(C4<>"",D4<>""),D4-C4,"") | F4: =IF(C4<>"",Certificate_Input!C21,"") | G4: =IF(E4="","",IF(ABS(E4)<=F4,"PASS","FAIL"))
B5: 3 | E5: =IF(AND(C5<>"",D5<>""),D5-C5,"") | F5: =IF(C5<>"",Certificate_Input!C21,"") | G5: =IF(E5="","",IF(ABS(E5)<=F5,"PASS","FAIL"))
B6: 4 | E6: =IF(AND(C6<>"",D6<>""),D6-C6,"") | F6: =IF(C6<>"",Certificate_Input!C21,"") | G6: =IF(E6="","",IF(ABS(E6)<=F6,"PASS","FAIL"))
B7: 5 | E7: =IF(AND(C7<>"",D7<>""),D7-C7,"") | F7: =IF(C7<>"",Certificate_Input!C21,"") | G7: =IF(E7="","",IF(ABS(E7)<=F7,"PASS","FAIL"))
B8: 6 | E8: =IF(AND(C8<>"",D8<>""),D8-C8,"") | F8: =IF(C8<>"",Certificate_Input!C21,"") | G8: =IF(E8="","",IF(ABS(E8)<=F8,"PASS","FAIL"))
B9: 7 | E9: =IF(AND(C9<>"",D9<>""),D9-C9,"") | F9: =IF(C9<>"",Certificate_Input!C21,"") | G9: =IF(E9="","",IF(ABS(E9)<=F9,"PASS","FAIL"))
B10: 8 | E10: =IF(AND(C10<>"",D10<>""),D10-C10,"") | F10: =IF(C10<>"",Certificate_Input!C21,"") | G10: =IF(E10="","",IF(ABS(E10)<=F10,"PASS","FAIL"))
B11: 9 | E11: =IF(AND(C11<>"",D11<>""),D11-C11,"") | F11: =IF(C11<>"",Certificate_Input!C21,"") | G11: =IF(E11="","",IF(ABS(E11)<=F11,"PASS","FAIL"))
B12: 10 | E12: =IF(AND(C12<>"",D12<>""),D12-C12,"") | F12: =IF(C12<>"",Certificate_Input!C21,"") | G12: =IF(E12="","",IF(ABS(E12)<=F12,"PASS","FAIL"))
B13: 11 | E13: =IF(AND(C13<>"",D13<>""),D13-C13,"") | F13: =IF(C13<>"",Certificate_Input!C21,"") | G13: =IF(E13="","",IF(ABS(E13)<=F13,"PASS","FAIL"))
B14: 12 | E14: =IF(AND(C14<>"",D14<>""),D14-C14,"") | F14: =IF(C14<>"",Certificate_Input!C21,"") | G14: =IF(E14="","",IF(ABS(E14)<=F14,"PASS","FAIL"))
B15: 13 | E15: =IF(AND(C15<>"",D15<>""),D15-C15,"") | F15: =IF(C15<>"",Certificate_Input!C21,"") | G15: =IF(E15="","",IF(ABS(E15)<=F15,"PASS","FAIL"))
B16: 14 | E16: =IF(AND(C16<>"",D16<>""),D16-C16,"") | F16: =IF(C16<>"",Certificate_Input!C21,"") | G16: =IF(E16="","",IF(ABS(E16)<=F16,"PASS","FAIL"))
B17: 15 | E17: =IF(AND(C17<>"",D17<>""),D17-C17,"") | F17: =IF(C17<>"",Certificate_Input!C21,"") | G17: =IF(E17="","",IF(ABS(E17)<=F17,"PASS","FAIL"))
B19: TABLE 2: AFTER CALIBRATION — DETECTOR RESPONSE
B20: # | C20: Set Point | D20: Actual Reading | E20: Deviation | F20: Tolerance (+/-) | G20: Conformance | H20: Section Result
B21: 1 | E21: =IF(AND(C21<>"",D21<>""),D21-C21,"") | F21: =IF(C21<>"",Certificate_Input!C21,"") | G21: =IF(E21="","",IF(ABS(E21)<=F21,"PASS","FAIL")) | H21: =IF(COUNTBLANK(G21:G35)=15,"",IF(COUNTIF(G21:G35,"FAIL")>0,"FAIL","PASS"))
B22: 2 | E22: =IF(AND(C22<>"",D22<>""),D22-C22,"") | F22: =IF(C22<>"",Certificate_Input!C21,"") | G22: =IF(E22="","",IF(ABS(E22)<=F22,"PASS","FAIL"))
B23: 3 | E23: =IF(AND(C23<>"",D23<>""),D23-C23,"") | F23: =IF(C23<>"",Certificate_Input!C21,"") | G23: =IF(E23="","",IF(ABS(E23)<=F23,"PASS","FAIL"))
B24: 4 | E24: =IF(AND(C24<>"",D24<>""),D24-C24,"") | F24: =IF(C24<>"",Certificate_Input!C21,"") | G24: =IF(E24="","",IF(ABS(E24)<=F24,"PASS","FAIL"))
B25: 5 | E25: =IF(AND(C25<>"",D25<>""),D25-C25,"") | F25: =IF(C25<>"",Certificate_Input!C21,"") | G25: =IF(E25="","",IF(ABS(E25)<=F25,"PASS","FAIL"))
B26: 6 | E26: =IF(AND(C26<>"",D26<>""),D26-C26,"") | F26: =IF(C26<>"",Certificate_Input!C21,"") | G26: =IF(E26="","",IF(ABS(E26)<=F26,"PASS","FAIL"))
B27: 7 | E27: =IF(AND(C27<>"",D27<>""),D27-C27,"") | F27: =IF(C27<>"",Certificate_Input!C21,"") | G27: =IF(E27="","",IF(ABS(E27)<=F27,"PASS","FAIL"))
B28: 8 | E28: =IF(AND(C28<>"",D28<>""),D28-C28,"") | F28: =IF(C28<>"",Certificate_Input!C21,"") | G28: =IF(E28="","",IF(ABS(E28)<=F28,"PASS","FAIL"))
B29: 9 | E29: =IF(AND(C29<>"",D29<>""),D29-C29,"") | F29: =IF(C29<>"",Certificate_Input!C21,"") | G29: =IF(E29="","",IF(ABS(E29)<=F29,"PASS","FAIL"))
B30: 10 | E30: =IF(AND(C30<>"",D30<>""),D30-C30,"") | F30: =IF(C30<>"",Certificate_Input!C21,"") | G30: =IF(E30="","",IF(ABS(E30)<=F30,"PASS","FAIL"))
B31: 11 | E31: =IF(AND(C31<>"",D31<>""),D31-C31,"") | F31: =IF(C31<>"",Certificate_Input!C21,"") | G31: =IF(E31="","",IF(ABS(E31)<=F31,"PASS","FAIL"))
B32: 12 | E32: =IF(AND(C32<>"",D32<>""),D32-C32,"") | F32: =IF(C32<>"",Certificate_Input!C21,"") | G32: =IF(E32="","",IF(ABS(E32)<=F32,"PASS","FAIL"))
B33: 13 | E33: =IF(AND(C33<>"",D33<>""),D33-C33,"") | F33: =IF(C33<>"",Certificate_Input!C21,"") | G33: =IF(E33="","",IF(ABS(E33)<=F33,"PASS","FAIL"))
B34: 14 | E34: =IF(AND(C34<>"",D34<>""),D34-C34,"") | F34: =IF(C34<>"",Certificate_Input!C21,"") | G34: =IF(E34="","",IF(ABS(E34)<=F34,"PASS","FAIL"))
B35: 15 | E35: =IF(AND(C35<>"",D35<>""),D35-C35,"") | F35: =IF(C35<>"",Certificate_Input!C21,"") | G35: =IF(E35="","",IF(ABS(E35)<=F35,"PASS","FAIL"))
B37: TABLE 3: INCLINOMETER CHECK
B38: # | C38: Set Point | D38: Actual Reading | E38: Deviation | F38: Tolerance (+/-) | G38: Conformance | H38: Section Result
B39: 1 | E39: =IF(AND(C39<>"",D39<>""),D39-C39,"") | F39: =IF(C39<>"",Certificate_Input!C22,"") | G39: =IF(E39="","",IF(ABS(E39)<=F39,"PASS","FAIL")) | H39: =IF(COUNTBLANK(G39:G53)=15,"",IF(COUNTIF(G39:G53,"FAIL")>0,"FAIL","PASS"))
B40: 2 | E40: =IF(AND(C40<>"",D40<>""),D40-C40,"") | F40: =IF(C40<>"",Certificate_Input!C22,"") | G40: =IF(E40="","",IF(ABS(E40)<=F40,"PASS","FAIL"))
B41: 3 | E41: =IF(AND(C41<>"",D41<>""),D41-C41,"") | F41: =IF(C41<>"",Certificate_Input!C22,"") | G41: =IF(E41="","",IF(ABS(E41)<=F41,"PASS","FAIL"))
B42: 4 | E42: =IF(AND(C42<>"",D42<>""),D42-C42,"") | F42: =IF(C42<>"",Certificate_Input!C22,"") | G42: =IF(E42="","",IF(ABS(E42)<=F42,"PASS","FAIL"))
...

Sheet Reference_Standards
B1: REFERENCE STANDARDS & TRACEABILITY
B3: # | C3: Reference Standard | D3: Manufacturer | E3: Serial Number | F3: Certificate Number | G3: Calibration Due | H3: Traceability
B4: 1
B5: 2
B6: 3
B7: 4
B8: 5
B9: 6
B10: 7
B11: 8
B12: 9
B13: 10

Sheet Audit_Log
B1: AUDIT LOG — CERTIFICATE CHANGE HISTORY
B2: Record all changes, reviews, and approvals below.
B4: # | C4: Date | D4: Action | E4: Performed By | F4: Description | G4: Verified By
B5: 1 | C5: 2026-03-26 | D5: Certificate Created | E5: System | F5: Initial certificate template generated
B6: 2
B7: 3
B8: 4
B9: 5
B10: 6
B11: 7
B12: 8
B13: 9
B14: 10
B15: 11
B16: 12
B17: 13
... B55: 51
