Workbook
Name Acceleration: 'Linfit Worksheet'!$W$1:$W$4
Name CalibrationDate: [1]Data!$A$22
Name CalibrationDueDate: [1]Data!$B$22
Name CalibrationID: [1]Data!$A$39
Name Customer: [1]Data!$A$38
Name CustomerAddress1: [1]Data!$C$38
Name CustomerAddress2: [1]Data!$D$38
Name CustomerAddress3: [1]Data!$E$38
Name Description: [1]Data!$A$7
Name Displacement: 'Linfit Worksheet'!$Y$1:$Y$4
Name DLinMeasureRangeUnit: 'Linfit Worksheet'!$AD$2
Name Humidity: [1]Data!$A$31
Name HumidityUnits: [1]Data!$B$31
Name IDNumber: [1]Data!$A$6
Name LinearityAsFound: [1]Data!$C$28
Name LinearityAsLeft: [1]Data!$C$29
Name LinearityAxis: [1]Data!$B$24
Name LinearityCalibrationMethod: [1]Data!$B$41
Name LinearityMeasured: [1]Data!$A$46
Name LinearityMeasuredUnits: [1]Data!$B$46
Name LinearityNotes: [1]Data!$A$20
Name LinearityProcedureNote: [1]Data!$B$43
Name LinearityReproductionNote: [1]Data!$B$42
Name LinearitySensitivity: [1]Data!$A$45
Name LinearitySensitivityUnits: [1]Data!$B$45
Name LinearityStationNote: [1]Data!$B$44
Name LinearityTechnician: [1]Data!$B$18
Name LinearityTestFreq: [1]Data!$A$47
Name LinearityTestFreqUnits: [1]Data!$B$47
Name LinearityTitle: [1]Data!$B$2
Name LinearityTraceabilityNote: [1]Data!$B$40
Name Manufacturer: [1]Data!$A$3
Name MeasurementRange: [1]Data!$A$33
Name MeasurementRangeUnits: [1]Data!$B$33
Name MeasurementResolution: [1]Data!$A$34
Name MeasurementResolutionUnits: [1]Data!$B$34
Name MinAmplitude: 'Vib Analyzer Data'!$B$38
Name MinAmpXaxis: 'Vib Analyzer Data'!$B$38
Name MinfreqXaxis: 'Vib Analyzer Data'!$B$39
Name Model: [1]Data!$A$4
Name pvc_route: 'Route Creator'!$B$8
Name PVCFWVers: 'Linfit Worksheet'!$AF$1:$AF$2
Name ResonantFrequency: [1]Data!$A$16
Name ResonantFrequencyUnits: [1]Data!$B$16
Name RouteType: 'Linfit Worksheet'!$AE$1:$AE$2
Name SensitivityPrecision: [1]Data!$C$1
Name SensUnits: 'Linfit Worksheet'!$AB$1:$AB$10
Name Serial: [1]Data!$A$5
Name SLinMeasureRangeUnit: 'Linfit Worksheet'!$AD$1
Name SystemUnits: [1]Data!$A$48
Name TablePrecision: [1]Data!$E$1
Name TemperatureEng: [1]Data!$C$30
Name TemperatureEngUnits: [1]Data!$D$30
Name TemperatureMet: [1]Data!$A$30
Name TemperatureMetUnits: [1]Data!$B$30
Name TemperatureRangeEngMax: [1]Data!$B$36
Name TemperatureRangeEngMin: [1]Data!$A$36
Name TemperatureRangeMetMax: [1]Data!$B$35
Name TemperatureRangeMetMin: [1]Data!$A$35
Name TypeOfMotion: 'Linfit Worksheet'!$V$1:$V$3

Sheet FRData
E1: Create Calibration Certificate
E2: in pC/g (mV/g data only)
C3: Portable Vibration Calibrator
C4: Report Generation Spreadsheet
C5: ='Linfit Worksheet'!L29
A8: Enter Reference Frequency | B8: 100
B9: =IF($A$12="","",$A$12) | D9: =IF($D$8="","","mV/pC")
A10: Frequency Response Data Table
A11: Frequency | B11: Amplitude | C11: Sensitivity | D11: Deviation
A12: =IF(FRRaw!C13<>"",FRRaw!C13,"") | B12: =IF(FRRaw!G13<>"",FRRaw!G13,"") | C12: =IF(AND(FRRaw!I12, FRRaw!E13 = "mV/g"),"pC/g",FRRaw!E13) | D12: %
A13: =IF(FRRaw!B13>0,FRRaw!B13,"") | B13: =IF(FRRaw!B13>0,FIXED(FRRaw!F13,2),"") | C13: =IF((AND(FRRaw!$I$12, FRRaw!$E$13 = "mV/g")), IF(FRRaw!B13,( IF(FRRaw!B13,FRRaw!D13,"")/FRData!$D$8), ""), IF(FRRaw!B13,FRRaw!D13,"")) | D13: =IF(A13="","",100*(C13/VLOOKUP($B$8,FRData!$A$13:$C$42,3,0.01)-1))
A14: =IF(FRRaw!B14>0,FRRaw!B14,"") | B14: =IF(FRRaw!B14>0,FIXED(FRRaw!F14,2),"") | C14: =IF((AND(FRRaw!$I$12, FRRaw!$E$13 = "mV/g")), IF(FRRaw!B14,( IF(FRRaw!B14,FRRaw!D14,"")/FRData!$D$8), ""), IF(FRRaw!B14,FRRaw!D14,"")) | D14: =IF(A14="","",100*(C14/VLOOKUP($B$8,FRData!$A$13:$C$42,3,0.01)-1))
A15: =IF(FRRaw!B15>0,FRRaw!B15,"") | B15: =IF(FRRaw!B15>0,FIXED(FRRaw!F15,2),"") | C15: =IF((AND(FRRaw!$I$12, FRRaw!$E$13 = "mV/g")), IF(FRRaw!B15,( IF(FRRaw!B15,FRRaw!D15,"")/FRData!$D$8), ""), IF(FRRaw!B15,FRRaw!D15,"")) | D15: =IF(A15="","",100*(C15/VLOOKUP($B$8,FRData!$A$13:$C$42,3,0.01)-1))
A16: =IF(FRRaw!B16>0,FRRaw!B16,"") | B16: =IF(FRRaw!B16>0,FIXED(FRRaw!F16,2),"") | C16: =IF((AND(FRRaw!$I$12, FRRaw!$E$13 = "mV/g")), IF(FRRaw!B16,( IF(FRRaw!B16,FRRaw!D16,"")/FRData!$D$8), ""), IF(FRRaw!B16,FRRaw!D16,"")) | D16: =IF(A16="","",100*(C16/VLOOKUP($B$8,FRData!$A$13:$C$42,3,0.01)-1))
A17: =IF(FRRaw!B17>0,FRRaw!B17,"") | B17: =IF(FRRaw!B17>0,FIXED(FRRaw!F17,2),"") | C17: =IF((AND(FRRaw!$I$12, FRRaw!$E$13 = "mV/g")), IF(FRRaw!B17,( IF(FRRaw!B17,FRRaw!D17,"")/FRData!$D$8), ""), IF(FRRaw!B17,FRRaw!D17,"")) | D17: =IF(A17="","",100*(C17/VLOOKUP($B$8,FRData!$A$13:$C$42,3,0.01)-1))
A18: =IF(FRRaw!B18>0,FRRaw!B18,"") | B18: =IF(FRRaw!B18>0,FIXED(FRRaw!F18,2),"") | C18: =IF((AND(FRRaw!$I$12, FRRaw!$E$13 = "mV/g")), IF(FRRaw!B18,( IF(FRRaw!B18,FRRaw!D18,"")/FRData!$D$8), ""), IF(FRRaw!B18,FRRaw!D18,"")) | D18: =IF(A18="","",100*(C18/VLOOKUP($B$8,FRData!$A$13:$C$42,3,0.01)-1))
A19: =IF(FRRaw!B19>0,FRRaw!B19,"") | B19: =IF(FRRaw!B19>0,FIXED(FRRaw!F19,2),"") | C19: =IF((AND(FRRaw!$I$12, FRRaw!$E$13 = "mV/g")), IF(FRRaw!B19,( IF(FRRaw!B19,FRRaw!D19,"")/FRData!$D$8), ""), IF(FRRaw!B19,FRRaw!D19,"")) | D19: =IF(A19="","",100*(C19/VLOOKUP($B$8,FRData!$A$13:$C$42,3,0.01)-1))
A20: =IF(FRRaw!B20>0,FRRaw!B20,"") | B20: =IF(FRRaw!B20>0,FIXED(FRRaw!F20,2),"") | C20: =IF((AND(FRRaw!$I$12, FRRaw!$E$13 = "mV/g")), IF(FRRaw!B20,( IF(FRRaw!B20,FRRaw!D20,"")/FRData!$D$8), ""), IF(FRRaw!B20,FRRaw!D20,"")) | D20: =IF(A20="","",100*(C20/VLOOKUP($B$8,FRData!$A$13:$C$42,3,0.01)-1))
A21: =IF(FRRaw!B21>0,FRRaw!B21,"") | B21: =IF(FRRaw!B21>0,FIXED(FRRaw!F21,2),"") | C21: =IF((AND(FRRaw!$I$12, FRRaw!$E$13 = "mV/g")), IF(FRRaw!B21,( IF(FRRaw!B21,FRRaw!D21,"")/FRData!$D$8), ""), IF(FRRaw!B21,FRRaw!D21,"")) | D21: =IF(A21="","",100*(C21/VLOOKUP($B$8,FRData!$A$13:$C$42,3,0.01)-1))
A22: =IF(FRRaw!B22>0,FRRaw!B22,"") | B22: =IF(FRRaw!B22>0,FIXED(FRRaw!F22,2),"") | C22: =IF((AND(FRRaw!$I$12, FRRaw!$E$13 = "mV/g")), IF(FRRaw!B22,( IF(FRRaw!B22,FRRaw!D22,"")/FRData!$D$8), ""), IF(FRRaw!B22,FRRaw!D22,"")) | D22: =IF(A22="","",100*(C22/VLOOKUP($B$8,FRData!$A$13:$C$42,3,0.01)-1))
A23: =IF(FRRaw!B23>0,FRRaw!B23,"") | B23: =IF(FRRaw!B23>0,FIXED(FRRaw!F23,2),"") | C23: =IF((AND(FRRaw!$I$12, FRRaw!$E$13 = "mV/g")), IF(FRRaw!B23,( IF(FRRaw!B23,FRRaw!D23,"")/FRData!$D$8), ""), IF(FRRaw!B23,FRRaw!D23,"")) | D23: =IF(A23="","",100*(C23/VLOOKUP($B$8,FRData!$A$13:$C$42,3,0.01)-1))
A24: =IF(FRRaw!B24>0,FRRaw!B24,"") | B24: =IF(FRRaw!B24>0,FIXED(FRRaw!F24,2),"") | C24: =IF((AND(FRRaw!$I$12, FRRaw!$E$13 = "mV/g")), IF(FRRaw!B24,( IF(FRRaw!B24,FRRaw!D24,"")/FRData!$D$8), ""), IF(FRRaw!B24,FRRaw!D24,"")) | D24: =IF(A24="","",100*(C24/VLOOKUP($B$8,FRData!$A$13:$C$42,3,0.01)-1))
... A42: =IF(FRRaw!B42>0,FRRaw!B42,"") | B42: =IF(FRRaw!B42>0,FIXED(FRRaw!F42,2),"") | C42: =IF((AND(FRRaw!$I$12, FRRaw!$E$13 = "mV/g")), IF(FRRaw!B42,( IF(FRRaw!B42,FRRaw!D42,"")/FRData!$D$8), ""), IF(FRRaw!B42,FRRaw!D42,"")) | D42: =IF(A42="","",100*(C42/VLOOKUP($B$8,FRData!$A$13:$C$42,3,0.01)-1))

Sheet LINData
D3: Portable Vibration Calibrator | G3: 1) Enter units for displacement and output
D4: Report Generation Spreadsheet
D5: ='Linfit Worksheet'!L29 | G5: 2) Enter measured data
B7: FALSE
A10: Dynamic Linearity Data Table | G10: Static Proximity Probe / 4-20 mA Vibration Sensor Calibration Data Table
A11: Test Frequency: | B11: =IF(LINRaw!B13<>"",LINRaw!B13,"") | C11: =IF(LINRaw!C13<>"",LINRaw!C13,"") | D11: Max Linearity: | E11: =FIXED(MAX('Linfit Worksheet'!G4:G19),2)&" %" | J11: Max Linearity: | K11: =IF(K15<>"",FIXED(MAX(K15:K39)*100,2),"0.00")&" %"
A12: Index | B12: Input | C12: Output | D12: Sensitivity | E12: Linearity | G12: Index | H12: Acceleration | I12: Output | J12: Sensitivity | K12: Linearity
B13: =IF(LINRaw!G13<>"",LINRaw!G13,"") | C13: =IF(D13<>0,LEFT(D13,FIND("/",D13,1)-1),"") | D13: =LINRaw!E13 | E13: % | H13: g pk | I13: mV | J13: =I13&"/"&'Linfit Worksheet'!AD1 | K13: %
A14: 1 | B14: =IF(LINRaw!B13>0,LINRaw!F13,"") | C14: =IF(B14<>"",D14*B14,"") | D14: =IF(LINRaw!B13>0,LINRaw!D13,"") | E14: ='Linfit Worksheet'!F4 | G14: Starting Point
A15: 2 | B15: =IF(LINRaw!B14>0,LINRaw!F14,"") | C15: =IF(B15<>"",D15*B15,"") | D15: =IF(LINRaw!B14>0,LINRaw!D14,"") | E15: ='Linfit Worksheet'!F5 | G15: 1 | J15: =IF(H15<>"",IF(I15<>"",(I15-I14)/(H15-H14),""),"") | K15: =IF(H15<>"",IF(I15<>"",'Linfit Worksheet'!N4,""),"")
A16: 3 | B16: =IF(LINRaw!B15>0,LINRaw!F15,"") | C16: =IF(B16<>"",D16*B16,"") | D16: =IF(LINRaw!B15>0,LINRaw!D15,"") | E16: ='Linfit Worksheet'!F6 | G16: 2 | J16: =IF(H16<>"",IF(I16<>"",(I16-I15)/(H16-H15),""),"") | K16: =IF(H16<>"",IF(I16<>"",'Linfit Worksheet'!N5,""),"")
A17: 4 | B17: =IF(LINRaw!B16>0,LINRaw!F16,"") | C17: =IF(B17<>"",D17*B17,"") | D17: =IF(LINRaw!B16>0,LINRaw!D16,"") | E17: ='Linfit Worksheet'!F7 | G17: 3 | J17: =IF(H17<>"",IF(I17<>"",(I17-I16)/(H17-H16),""),"") | K17: =IF(H17<>"",IF(I17<>"",'Linfit Worksheet'!N6,""),"")
A18: 5 | B18: =IF(LINRaw!B17>0,LINRaw!F17,"") | C18: =IF(B18<>"",D18*B18,"") | D18: =IF(LINRaw!B17>0,LINRaw!D17,"") | E18: ='Linfit Worksheet'!F8 | G18: 4 | J18: =IF(H18<>"",IF(I18<>"",(I18-I17)/(H18-H17),""),"") | K18: =IF(H18<>"",IF(I18<>"",'Linfit Worksheet'!N7,""),"")
A19: 6 | B19: =IF(LINRaw!B18>0,LINRaw!F18,"") | C19: =IF(B19<>"",D19*B19,"") | D19: =IF(LINRaw!B18>0,LINRaw!D18,"") | E19: ='Linfit Worksheet'!F9 | G19: 5 | J19: =IF(H19<>"",IF(I19<>"",(I19-I18)/(H19-H18),""),"") | K19: =IF(H19<>"",IF(I19<>"",'Linfit Worksheet'!N8,""),"")
A20: 7 | B20: =IF(LINRaw!B19>0,LINRaw!F19,"") | C20: =IF(B20<>"",D20*B20,"") | D20: =IF(LINRaw!B19>0,LINRaw!D19,"") | E20: ='Linfit Worksheet'!F10 | G20: 6 | J20: =IF(H20<>"",IF(I20<>"",(I20-I19)/(H20-H19),""),"") | K20: =IF(H20<>"",IF(I20<>"",'Linfit Worksheet'!N9,""),"")
A21: 8 | B21: =IF(LINRaw!B20>0,LINRaw!F20,"") | C21: =IF(B21<>"",D21*B21,"") | D21: =IF(LINRaw!B20>0,LINRaw!D20,"") | E21: ='Linfit Worksheet'!F11 | G21: 7 | J21: =IF(H21<>"",IF(I21<>"",(I21-I20)/(H21-H20),""),"") | K21: =IF(H21<>"",IF(I21<>"",'Linfit Worksheet'!N10,""),"")
A22: 9 | B22: =IF(LINRaw!B21>0,LINRaw!F21,"") | C22: =IF(B22<>"",D22*B22,"") | D22: =IF(LINRaw!B21>0,LINRaw!D21,"") | E22: ='Linfit Worksheet'!F12 | G22: 8 | J22: =IF(H22<>"",IF(I22<>"",(I22-I21)/(H22-H21),""),"") | K22: =IF(H22<>"",IF(I22<>"",'Linfit Worksheet'!N11,""),"")
A23: 10 | B23: =IF(LINRaw!B22>0,LINRaw!F22,"") | C23: =IF(B23<>"",D23*B23,"") | D23: =IF(LINRaw!B22>0,LINRaw!D22,"") | E23: ='Linfit Worksheet'!F13 | G23: 9 | J23: =IF(H23<>"",IF(I23<>"",(I23-I22)/(H23-H22),""),"") | K23: =IF(H23<>"",IF(I23<>"",'Linfit Worksheet'!N12,""),"")
A24: 11 | B24: =IF(LINRaw!B23>0,LINRaw!F23,"") | C24: =IF(B24<>"",D24*B24,"") | D24: =IF(LINRaw!B23>0,LINRaw!D23,"") | E24: ='Linfit Worksheet'!F14 | G24: 10 | J24: =IF(H24<>"",IF(I24<>"",(I24-I23)/(H24-H23),""),"") | K24: =IF(H24<>"",IF(I24<>"",'Linfit Worksheet'!N13,""),"")
A25: 12 | B25: =IF(LINRaw!B24>0,LINRaw!F24,"") | C25: =IF(B25<>"",D25*B25,"") | D25: =IF(LINRaw!B24>0,LINRaw!D24,"") | E25: ='Linfit Worksheet'!F15 | G25: 11 | J25: =IF(H25<>"",IF(I25<>"",(I25-I24)/(H25-H24),""),"") | K25: =IF(H25<>"",IF(I25<>"",'Linfit Worksheet'!N14,""),"")
A26: 13 | B26: =IF(LINRaw!B25>0,LINRaw!F25,"") | C26: =IF(B26<>"",D26*B26,"") | D26: =IF(LINRaw!B25>0,LINRaw!D25,"") | E26: ='Linfit Worksheet'!F16 | G26: 12 | J26: =IF(H26<>"",IF(I26<>"",(I26-I25)/(H26-H25),""),"") | K26: =IF(H26<>"",IF(I26<>"",'Linfit Worksheet'!N15,""),"")
... A39: 26 | B39: =IF(LINRaw!B38>0,LINRaw!F38,"") | C39: =IF(B39<>"",D39*B39,"") | D39: =IF(LINRaw!B38>0,LINRaw!D38,"") | E39: ='Linfit Worksheet'!F29 | G39: 25 | J39: =IF(H39<>"",IF(I39<>"",(I39-I38)/(H39-H38),""),"") | K39: =IF(H39<>"",IF(I39<>"",'Linfit Worksheet'!N28,""),"")
A40: 27 | B40: =IF(LINRaw!B39>0,LINRaw!F39,"") | C40: =IF(B40<>"",D40*B40,"") | D40: =IF(LINRaw!B39>0,LINRaw!D39,"") | E40: ='Linfit Worksheet'!F30
A41: 28 | B41: =IF(LINRaw!B40>0,LINRaw!F40,"") | C41: =IF(B41<>"",D41*B41,"") | D41: =IF(LINRaw!B40>0,LINRaw!D40,"") | E41: ='Linfit Worksheet'!F31
A42: 29 | B42: =IF(LINRaw!B41>0,LINRaw!F41,"") | C42: =IF(B42<>"",D42*B42,"") | D42: =IF(LINRaw!B41>0,LINRaw!D41,"") | E42: ='Linfit Worksheet'!F32
A43: 30 | B43: =IF(LINRaw!B42>0,LINRaw!F42,"") | C43: =IF(B43<>"",D43*B43,"") | D43: =IF(LINRaw!B42>0,LINRaw!D42,"") | E43: ='Linfit Worksheet'!F33

Sheet Route Creator
C3: Portable Vibration Calibrator
C4: Calibration Route Generation Spreadsheet
C5: ='Linfit Worksheet'!L29
C7: PVC Version
A8: Route Name | C8: Route Type | E8: Sensor Type
A9: Frequency Unit | C9: Lower Bound | E9: Sensor MN
A10: Amplitude | C10: Upper Bound
A11: Amplitude Unit | C11: Nominal Sens.
A13: Frequency | B13: Amplitude | C13: Amplitude Unit | D13: Lower Bound | E13: Upper Bound

Sheet Vib Analyzer Data
A2: ~ Vibration Analyzer Certification ~
B4: Analyzer/Meter Information * | E4: Analyzer Settings *
B5: Manufacturer: | C5: Emerson CSI | E5: Analyzer mode: | H5: 1
B6: Model Number: | C6: 2140 | E6: Frequency Max: | H6: 1000
B7: Serial Number: | C7: B21401237749 | E7: Frequncy Min: | H7: 10
B8: Cal. Tech: | C8: Andrew Robb | G8: Frequency Unit: | H8: 1
B9: Cal. date: | C9: 31/03/2026 | E9: Lines of Resolution: | H9: 1600
B10: Cal. due: | C10: 30/03/2027 | E10: Averaging Points: | H10: 4
E11: Window Type: | H11: 1
E12: Analyzer Sensor Input Sensitivity: | H12: 0.1
G13: Unit: | H13: 1
B14: Test Equipment *
B15: Description | C15: Model Number | D15: Serial Number | F15: Cal date | G15: Cal. Sensitivity @ 100Hz | H15: Unit | I15: Meas. Sensitivity @ 100Hz | J15: Unit | K15: % Tolerance | L15: % Deviation
B16: PVC | C16: 9110D | D16: 11755 | F16: 45973 | G16: 1.06 | H16: mV/g | I16: 1.05 | J16: mV/g | K16: 0.03 | L16: =IF(OR(G16="",I16=""),"",I16/G16-1)
B17: Sensor | C17: A0760GP | D17: P9713 | F17: 46108 | G17: 1 | H17: mV/g | I17: 0.97 | J17: mV/g | K17: 0.05 | L17: =IF(OR(G17="",I17=""),"",I17/G17-1)
B18: DMM
G21: 0.75
C22: 1 | G22: 1
A24: No. | B24: Known Value | D24: Measured Value | G24: % Deviation | J24: Test *
B25: Amplitude | C25: Frequency | D25: Amplitude | F25: Frequency | G25: Amplitude | H25: Frequency | J25: Test Frequency: | K25: 50
A26: 1 | B26: 0.1 | C26: 50 | D26: 0.073 | F26: 50 | G26: =IF(OR(B26="",D26=""),"",(D26/B26-1)*100) | H26: =IF(OR(C26="",F26=""),"",(F26/C26-1)*100) | J26: Freq Unit: | K26: 1
A27: 2 | B27: 0.2 | C27: 50 | D27: 0.147 | F27: 50 | G27: =IF(OR(B27="",D27=""),"",(D27/B27-1)*100) | H27: =IF(OR(C27="",F27=""),"",(F27/C27-1)*100)
A28: 3 | B28: 0.5 | C28: 50 | D28: 0.366 | F28: 50 | G28: =IF(OR(B28="",D28=""),"",(D28/B28-1)*100) | H28: =IF(OR(C28="",F28=""),"",(F28/C28-1)*100) | J28: Test Amplitude: | K28: 1
A29: 4 | B29: 0.75 | C29: 50 | D29: 0.549 | F29: 50 | G29: =IF(OR(B29="",D29=""),"",(D29/B29-1)*100) | H29: =IF(OR(C29="",F29=""),"",(F29/C29-1)*100) | J29: Amp. Unit: | K29: 8
A30: 5 | B30: 1 | C30: 50 | D30: 0.733 | F30: 50 | G30: =IF(OR(B30="",D30=""),"",(D30/B30-1)*100) | H30: =IF(OR(C30="",F30=""),"",(F30/C30-1)*100)
A31: 6 | B31: 1.25 | C31: 50 | D31: 0.915 | F31: 50 | G31: =IF(OR(B31="",D31=""),"",(D31/B31-1)*100) | H31: =IF(OR(C31="",F31=""),"",(F31/C31-1)*100)
A32: 7 | B32: 1.5 | C32: 50 | D32: 1.097 | F32: 50 | G32: =IF(OR(B32="",D32=""),"",(D32/B32-1)*100) | H32: =IF(OR(C32="",F32=""),"",(F32/C32-1)*100)
A33: 8 | G33: =IF(OR(B33="",D33=""),"",(D33/B33-1)*100) | H33: =IF(OR(C33="",F33=""),"",(F33/C33-1)*100)
A34: 9 | B34: 1 | C34: 10 | D34: 0.533 | F34: 10 | G34: =IF(OR(B34="",D34=""),"",(D34/B34-1)*100) | H34: =IF(OR(C34="",F34=""),"",(F34/C34-1)*100)
A35: 10 | B35: 1 | C35: 20 | D35: 0.729 | F35: 20 | G35: =IF(OR(B35="",D35=""),"",(D35/B35-1)*100) | H35: =IF(OR(C35="",F35=""),"",(F35/C35-1)*100)
A36: 11 | B36: 1 | C36: 30 | D36: 0.718 | F36: 30 | G36: =IF(OR(B36="",D36=""),"",(D36/B36-1)*100) | H36: =IF(OR(C36="",F36=""),"",(F36/C36-1)*100) | K36: =IF(OR(I36="",J36=""),"",#REF!/#REF!-1)
A37: 12 | B37: 1 | C37: 50 | D37: 0.733 | F37: 50 | G37: =IF(OR(B37="",D37=""),"",(D37/B37-1)*100) | H37: =IF(OR(C37="",F37=""),"",(F37/C37-1)*100)
A38: 13 | B38: 1 | C38: 60 | D38: 0.73 | F38: 60 | G38: =IF(OR(B38="",D38=""),"",(D38/B38-1)*100) | H38: =IF(OR(C38="",F38=""),"",(F38/C38-1)*100)
A39: 14 | B39: 1 | C39: 95 | D39: 0.717 | F39: 95 | G39: =IF(OR(B39="",D39=""),"",(D39/B39-1)*100) | H39: =IF(OR(C39="",F39=""),"",(F39/C39-1)*100)
A40: 15 | G40: =IF(OR(B40="",D40=""),"",(D40/B40-1)*100) | H40: =IF(OR(C40="",F40=""),"",(F40/C40-1)*100)

Sheet FRCert
B2: ~ Calibration Certificate ~
B4: Sensor Information: | E4: Calibration Data | I4: Transducer Specifications
B5: Model Number | C5: =IF(FRRaw!A5<>"",FRRaw!A5,"") | E5: ="Sensitivity @ "&VLOOKUP(FRData!B8,FRData!A13:A42,1)&" "&FRData!B9&":" | G5: =VLOOKUP(FRData!B8,FRData!A13:D42,3) | H5: =FRData!C12 | I5: Amp. Range: | L5: g
B6: Serial Number | C6: =IF(FRRaw!B5<>"",FRRaw!B5,"") | E6: Test Level: | G6: =FIXED(VLOOKUP(FRData!B8,FRData!A13:D42,2),2) | H6: =FRData!B12 | I6: Resolution: | L6: g
B7: Manufacturer | E7: =IF(FRRaw!I12,"Inline Charge Amp","") | I7: Resonant Freq: | L7: Hz
B8: ID Number | E8: =IF(FRRaw!I12,"Sensitivity:","") | G8: =IF(FRRaw!I12,FRData!D8,"") | H8: =IF(FRRaw!I12,"mV/pC","") | I8: Temp. Range: | L8: oC
B9: Description | I9: =IF(FRRaw!C5<>"","Axis:","") | K9: =IF(FRRaw!C5<>"",FRRaw!C5,"")
E16: Calibration Data:
E17: Sensitivity at | F17: =VLOOKUP(FRData!C8,FRData!A13:D21,3,0.01) | H17: =FRData!C12
E19: Ref. Frequency | F19: =FRData!C8 | H19: Hz
B26: Data Table
B27: ="Frequency ("&FRData!B9&")" | C27: Deviation (%) | E27: Notes
B28: =IF(FRData!A13<>"",FRData!A13,"") | C28: =IF(FRData!A13<>"",FRData!D13,"") | E28: Results relate only to the items calibrated.
B29: =IF(FRData!A14<>"",FRData!A14,"") | C29: =IF(FRData!A14<>"",FRData!D14,"") | E29: This certificate may not be reproduced except in full, without written permission.
B30: =IF(FRData!A15<>"",FRData!A15,"") | C30: =IF(FRData!A15<>"",FRData!D15,"") | E30: =IF(FRRaw!A6="", "","Traceable to "& FRRaw!$A$6 & IF(FRRaw!B6="", "", " and " & FRRaw!$B$6))
B31: =IF(FRData!A16<>"",FRData!A16,"") | C31: =IF(FRData!A16<>"",FRData!D16,"") | E31: ="This calibration was performed with Portable Vibration Calibrator: M/N: " & FRRaw!D3&", S/N: " &FRRaw!E3&", Firmware version "&FRRaw!F3&"."
B32: =IF(FRData!A17<>"",FRData!A17,"") | C32: =IF(FRData!A17<>"",FRData!D17,"") | E32: Back-to-Back Comparison per ISO 16063-21
B33: =IF(FRData!A18<>"",FRData!A18,"") | C33: =IF(FRData!A18<>"",FRData!D18,"")
B34: =IF(FRData!A19<>"",FRData!A19,"") | C34: =IF(FRData!A19<>"",FRData!D19,"")
B35: =IF(FRData!A20<>"",FRData!A20,"") | C35: =IF(FRData!A20<>"",FRData!D20,"")
B36: =IF(FRData!A21<>"",FRData!A21,"") | C36: =IF(FRData!A21<>"",FRData!D21,"") | E36: User Notes | F36: =IF(FRRaw!$D$5="","",FRRaw!$D$5)
B37: =IF(FRData!A22<>"",FRData!A22,"") | C37: =IF(FRData!A22<>"",FRData!D22,"")
B38: =IF(FRData!A23<>"",FRData!A23,"") | C38: =IF(FRData!A23<>"",FRData!D23,"")
B39: =IF(FRData!A24<>"",FRData!A24,"") | C39: =IF(FRData!A24<>"",FRData!D24,"")
B40: =IF(FRData!A25<>"",FRData!A25,"") | C40: =IF(FRData!A25<>"",FRData!D25,"")
B41: =IF(FRData!A26<>"",FRData!A26,"") | C41: =IF(FRData!A26<>"",FRData!D26,"") | E41: Customer:
B42: =IF(FRData!A27<>"",FRData!A27,"") | C42: =IF(FRData!A27<>"",FRData!D27,"")
B43: =IF(FRData!A28<>"",FRData!A28,"") | C43: =IF(FRData!A28<>"",FRData!D28,"")
B44: =IF(FRData!A29<>"",FRData!A29,"") | C44: =IF(FRData!A29<>"",FRData!D29,"")
B45: =IF(FRData!A30<>"",FRData!A30,"") | C45: =IF(FRData!A30<>"",FRData!D30,"")
B46: =IF(FRData!A31<>"",FRData!A31,"") | C46: =IF(FRData!A31<>"",FRData!D31,"")
B47: =IF(FRData!A32<>"",FRData!A32,"") | C47: =IF(FRData!A32<>"",FRData!D32,"")
B48: =IF(FRData!A33<>"",FRData!A33,"") | C48: =IF(FRData!A33<>"",FRData!D33,"") | E48: Unit Condition | I48: Lab Conditions
B49: =IF(FRData!A34<>"",FRData!A34,"") | C49: =IF(FRData!A34<>"",FRData!D34,"") | E49: As Found: | I49: Temperature: | L49: oC
B50: =IF(FRData!A35<>"",FRData!A35,"") | C50: =IF(FRData!A35<>"",FRData!D35,"") | E50: As Left: | I50: Humidity: | L50: %
B51: =IF(FRData!A36<>"",FRData!A36,"") | C51: =IF(FRData!A36<>"",FRData!D36,"")
B52: =IF(FRData!A37<>"",FRData!A37,"") | C52: =IF(FRData!A37<>"",FRData!D37,"")
B53: =IF(FRData!A38<>"",FRData!A38,"") | C53: =IF(FRData!A38<>"",FRData!D38,"")
B54: =IF(FRData!A39<>"",FRData!A39,"") | C54: =IF(FRData!A39<>"",FRData!D39,"") | E54: Approval Information
B55: =IF(FRData!A40<>"",FRData!A40,"") | C55: =IF(FRData!A40<>"",FRData!D40,"") | E55: Technician: | I55: Calibration Date: | K55: =FRRaw!B3
...

Sheet LINCert
A2: ~ Linearity Certificate ~
B4: Sensor Information | J4: Calibration Data | V4: Transducer Specifications
B5: Model Number: | E5: =IF(LINRaw!A5="","",LINRaw!A5) | J5: Sensitivity @ Test Freq.: | O5: =IF('Linfit Worksheet'!B7<1,FIXED('Linfit Worksheet'!B7,3),FIXED('Linfit Worksheet'!B7,3)) | R5: =LINData!$D$13 | V5: Amp. Range: | AB5: =DLinMeasureRangeUnit
B6: Serial Number: | E6: =IF(LINRaw!B5="","",LINRaw!B5) | V6: =IF(MeasurementResolution<0.000000001,"","Resolution:") | AB6: =IF(Y6<0.000000001,"",DLinMeasureRangeUnit)
B7: Manufacturer: | J7: Test Frequency | O7: =LINData!$B$11 | R7: =LINData!$C$11 | V7: Resonant Freq: | AB7: Hz
B8: ID Number: | V8: Temp. Range: | AB8: oC
J9: Linearity: | O9: =FIXED(LINData!$E$11*100,2) | R9: % | V9: =IF(LINRaw!C5<>"","Axis:","") | Y9: =IF(LINRaw!C5<>"",LINRaw!C5,"")
B10: Amplitude Linearity
B26: Data Table
B27: =LINData!B12&" ("&LINData!B13&")" | E27: ="Output ("&LINData!C13&")" | H27: Linearity (%) | L27: Notes
B28: =IF(LINData!B14<>"",IF(LINData!C14<>"",LINData!B14,""),"") | E28: =IF(LINData!B14<>"",IF(LINData!C14<>"",LINData!C14,""),"") | H28: =IF(LINData!B14<>"",IF(LINData!C14<>"",LINData!E14,""),"") | L28: Results relate only to the items calibrated.
B29: =IF(LINData!B15<>"",IF(LINData!C15<>"",LINData!B15,""),"") | E29: =IF(LINData!B15<>"",IF(LINData!C15<>"",LINData!C15,""),"") | H29: =IF(LINData!B15<>"",IF(LINData!C15<>"",LINData!E15,""),"") | L29: This certificate may not be reproduced except in full, without written permision.
B30: =IF(LINData!B16<>"",IF(LINData!C16<>"",LINData!B16,""),"") | E30: =IF(LINData!B16<>"",IF(LINData!C16<>"",LINData!C16,""),"") | H30: =IF(LINData!B16<>"",IF(LINData!C16<>"",LINData!E16,""),"") | L30: =IF(LINRaw!A6="", "","Traceable to "& LINRaw!$A$6 & IF(LINRaw!B6="", "", " and " & LINRaw!$B$6))
B31: =IF(LINData!B17<>"",IF(LINData!C17<>"",LINData!B17,""),"") | E31: =IF(LINData!B17<>"",IF(LINData!C17<>"",LINData!C17,""),"") | H31: =IF(LINData!B17<>"",IF(LINData!C17<>"",LINData!E17,""),"") | L31: ="This calibration was performed with Portable Vibration Calibrator: " &CHAR(10) &" M/N: " &LINRaw!D3&", S/N: " &LINRaw!E3&", Firmware version "&LINRaw!F3&"."
B32: =IF(LINData!B18<>"",IF(LINData!C18<>"",LINData!B18,""),"") | E32: =IF(LINData!B18<>"",IF(LINData!C18<>"",LINData!C18,""),"") | H32: =IF(LINData!B18<>"",IF(LINData!C18<>"",LINData!E18,""),"")
B33: =IF(LINData!B19<>"",IF(LINData!C19<>"",LINData!B19,""),"") | E33: =IF(LINData!B19<>"",IF(LINData!C19<>"",LINData!C19,""),"") | H33: =IF(LINData!B19<>"",IF(LINData!C19<>"",LINData!E19,""),"") | L33: Back-to-Back Comparison per ISO 16063-22
B34: =IF(LINData!B20<>"",IF(LINData!C20<>"",LINData!B20,""),"") | E34: =IF(LINData!B20<>"",IF(LINData!C20<>"",LINData!C20,""),"") | H34: =IF(LINData!B20<>"",IF(LINData!C20<>"",LINData!E20,""),"")
B35: =IF(LINData!B21<>"",IF(LINData!C21<>"",LINData!B21,""),"") | E35: =IF(LINData!B21<>"",IF(LINData!C21<>"",LINData!C21,""),"") | H35: =IF(LINData!B21<>"",IF(LINData!C21<>"",LINData!E21,""),"")
B36: =IF(LINData!B22<>"",IF(LINData!C22<>"",LINData!B22,""),"") | E36: =IF(LINData!B22<>"",IF(LINData!C22<>"",LINData!C22,""),"") | H36: =IF(LINData!B22<>"",IF(LINData!C22<>"",LINData!E22,""),"") | L36: User Notes | O36: =IF(LINRaw!$D$5="","",LINRaw!$D$5)
B37: =IF(LINData!B23<>"",IF(LINData!C23<>"",LINData!B23,""),"") | E37: =IF(LINData!B23<>"",IF(LINData!C23<>"",LINData!C23,""),"") | H37: =IF(LINData!B23<>"",IF(LINData!C23<>"",LINData!E23,""),"")
B38: =IF(LINData!B24<>"",IF(LINData!C24<>"",LINData!B24,""),"") | E38: =IF(LINData!B24<>"",IF(LINData!C24<>"",LINData!C24,""),"") | H38: =IF(LINData!B24<>"",IF(LINData!C24<>"",LINData!E24,""),"")
B39: =IF(LINData!B25<>"",IF(LINData!C25<>"",LINData!B25,""),"") | E39: =IF(LINData!B25<>"",IF(LINData!C25<>"",LINData!C25,""),"") | H39: =IF(LINData!B25<>"",IF(LINData!C25<>"",LINData!E25,""),"")
B40: =IF(LINData!B26<>"",IF(LINData!C26<>"",LINData!B26,""),"") | E40: =IF(LINData!B26<>"",IF(LINData!C26<>"",LINData!C26,""),"") | H40: =IF(LINData!B26<>"",IF(LINData!C26<>"",LINData!E26,""),"")
B41: =IF(LINData!B27<>"",IF(LINData!C27<>"",LINData!B27,""),"") | E41: =IF(LINData!B27<>"",IF(LINData!C27<>"",LINData!C27,""),"") | H41: =IF(LINData!B27<>"",IF(LINData!C27<>"",LINData!E27,""),"") | L41: Customer
B42: =IF(LINData!B28<>"",IF(LINData!C28<>"",LINData!B28,""),"") | E42: =IF(LINData!B28<>"",IF(LINData!C28<>"",LINData!C28,""),"") | H42: =IF(LINData!B28<>"",IF(LINData!C28<>"",LINData!E28,""),"")
B43: =IF(LINData!B29<>"",IF(LINData!C29<>"",LINData!B29,""),"") | E43: =IF(LINData!B29<>"",IF(LINData!C29<>"",LINData!C29,""),"") | H43: =IF(LINData!B29<>"",IF(LINData!C29<>"",LINData!E29,""),"")
B44: =IF(LINData!B30<>"",IF(LINData!C30<>"",LINData!B30,""),"") | E44: =IF(LINData!B30<>"",IF(LINData!C30<>"",LINData!C30,""),"") | H44: =IF(LINData!B30<>"",IF(LINData!C30<>"",LINData!E30,""),"")
B45: =IF(LINData!B31<>"",IF(LINData!C31<>"",LINData!B31,""),"") | E45: =IF(LINData!B31<>"",IF(LINData!C31<>"",LINData!C31,""),"") | H45: =IF(LINData!B31<>"",IF(LINData!C31<>"",LINData!E31,""),"")
B46: =IF(LINData!B32<>"",IF(LINData!C32<>"",LINData!B32,""),"") | E46: =IF(LINData!B32<>"",IF(LINData!C32<>"",LINData!C32,""),"") | H46: =IF(LINData!B32<>"",IF(LINData!C32<>"",LINData!E32,""),"")
B47: =IF(LINData!B33<>"",IF(LINData!C33<>"",LINData!B33,""),"") | E47: =IF(LINData!B33<>"",IF(LINData!C33<>"",LINData!C33,""),"") | H47: =IF(LINData!B33<>"",IF(LINData!C33<>"",LINData!E33,""),"") | L47: Unit Condition | U47: Lab Conditions
B48: =IF(LINData!B34<>"",IF(LINData!C34<>"",LINData!B34,""),"") | E48: =IF(LINData!B34<>"",IF(LINData!C34<>"",LINData!C34,""),"") | H48: =IF(LINData!B34<>"",IF(LINData!C34<>"",LINData!E34,""),"") | L48: As Found: | U48: Temperature: | AA48: °C
B49: =IF(LINData!B35<>"",IF(LINData!C35<>"",LINData!B35,""),"") | E49: =IF(LINData!B35<>"",IF(LINData!C35<>"",LINData!C35,""),"") | H49: =IF(LINData!B35<>"",IF(LINData!C35<>"",LINData!E35,""),"") | L49: As Left:
B50: =IF(LINData!B36<>"",IF(LINData!C36<>"",LINData!B36,""),"") | E50: =IF(LINData!B36<>"",IF(LINData!C36<>"",LINData!C36,""),"") | H50: =IF(LINData!B36<>"",IF(LINData!C36<>"",LINData!E36,""),"") | U50: Humidity: | AA50: %
B51: =IF(LINData!B37<>"",IF(LINData!C37<>"",LINData!B37,""),"") | E51: =IF(LINData!B37<>"",IF(LINData!C37<>"",LINData!C37,""),"") | H51: =IF(LINData!B37<>"",IF(LINData!C37<>"",LINData!E37,""),"")
B52: =IF(LINData!B38<>"",IF(LINData!C38<>"",LINData!B38,""),"") | E52: =IF(LINData!B38<>"",IF(LINData!C38<>"",LINData!C38,""),"") | H52: =IF(LINData!B38<>"",IF(LINData!C38<>"",LINData!E38,""),"")
B53: =IF(LINData!B39<>"",IF(LINData!C39<>"",LINData!B39,""),"") | E53: =IF(LINData!B39<>"",IF(LINData!C39<>"",LINData!C39,""),"") | H53: =IF(LINData!B39<>"",IF(LINData!C39<>"",LINData!E39,""),"")
B54: =IF(LINData!B40<>"",IF(LINData!C40<>"",LINData!B40,""),"") | E54: =IF(LINData!B40<>"",IF(LINData!C40<>"",LINData!C40,""),"") | H54: =IF(LINData!B40<>"",IF(LINData!C40<>"",LINData!E40,""),"") | L54: Approval Information
B55: =IF(LINData!B41<>"",IF(LINData!C41<>"",LINData!B41,""),"") | E55: =IF(LINData!B41<>"",IF(LINData!C41<>"",LINData!C41,""),"") | H55: =IF(LINData!B41<>"",IF(LINData!C41<>"",LINData!E41,""),"") | L55: Technician: | U55: Calibration Date: | Y55: =LINRaw!B3
B56: =IF(LINData!B42<>"",IF(LINData!C42<>"",LINData!B42,""),"") | E56: =IF(LINData!B42<>"",IF(LINData!C42<>"",LINData!C42,""),"") | H56: =IF(LINData!B42<>"",IF(LINData!C42<>"",LINData!E42,""),"") | L56: Approval: | U56: Calibration Time: | Y56: =LINRaw!C3
B57: =IF(LINData!B43<>"",IF(LINData!C43<>"",LINData!B43,""),"") | E57: =IF(LINData!B43<>"",IF(LINData!C43<>"",LINData!C43,""),"") | H57: =IF(LINData!B43<>"",IF(LINData!C43<>"",LINData!E43,""),"") | U57: Due Date:

Sheet SLINCert
A2: ~ Linearity Certificate ~
B4: Sensor Information | J4: Calibration Data | V4: Transducer Specifications
B5: Model Number: | J5: Sensitivity: | O5: =IF('Linfit Worksheet'!J12<>"",FIXED(ABS('Linfit Worksheet'!J12),3),"") | R5: ='Linfit Worksheet'!L2&"/"&'Linfit Worksheet'!K2 | V5: Amp. Range: | AB5: =SLinMeasureRangeUnit
B6: Serial Number: | V6: =IF(MeasurementResolution<0.000000001,"","Resolution:") | AB6: =IF(MeasurementResolution<0.000000001,"",SLinMeasureRangeUnit)
B7: Manufacturer: | J7: Linearity: | O7: =IF(LINData!K11<>"",FIXED(LINData!K11*100,2),"") | R7: % | V7: Resonant Freq: | AB7: =ResonantFrequencyUnits
B8: ID Number: | V8: Temp. Range: | AB8: oC
B10: Amplitude Linearity
B27: Data Table | L27: Notes
B28: =LINData!B12&" ("&LINData!H13&")" | E28: ="Output ("&LINData!I13&")" | H28: Linearity (%) | L28: Results relate only to the items calibrated.
L29: This certificate may not be reproduced except in full, without written permision.
B30: =IF('Linfit Worksheet'!K3<>"",IF('Linfit Worksheet'!L3<>"",'Linfit Worksheet'!K3,""),"") | E30: =IF('Linfit Worksheet'!K3<>"",IF('Linfit Worksheet'!L3<>"",'Linfit Worksheet'!L3,""),"") | H30: n/a | L30: Data Table is Normalized to Starting Point (-3V DC Nominal)
B31: =IF('Linfit Worksheet'!K4<>"",IF('Linfit Worksheet'!L4<>"",'Linfit Worksheet'!K4,""),"") | E31: =IF('Linfit Worksheet'!K4<>"",IF('Linfit Worksheet'!L4<>"",'Linfit Worksheet'!L4,""),"") | H31: =IF('Linfit Worksheet'!K4<>"",IF('Linfit Worksheet'!L4<>"",'Linfit Worksheet'!N4,""),"") | L31: Displacement data must be entered in ascending order from Starting Point
B32: =IF('Linfit Worksheet'!K5<>"",IF('Linfit Worksheet'!L5<>"",'Linfit Worksheet'!K5,""),"") | E32: =IF('Linfit Worksheet'!K5<>"",IF('Linfit Worksheet'!L5<>"",'Linfit Worksheet'!L5,""),"") | H32: =IF('Linfit Worksheet'!K5<>"",IF('Linfit Worksheet'!L5<>"",'Linfit Worksheet'!N5,""),"")
B33: =IF('Linfit Worksheet'!K6<>"",IF('Linfit Worksheet'!L6<>"",'Linfit Worksheet'!K6,""),"") | E33: =IF('Linfit Worksheet'!K6<>"",IF('Linfit Worksheet'!L6<>"",'Linfit Worksheet'!L6,""),"") | H33: =IF('Linfit Worksheet'!K6<>"",IF('Linfit Worksheet'!L6<>"",'Linfit Worksheet'!N6,""),"")
B34: =IF('Linfit Worksheet'!K7<>"",IF('Linfit Worksheet'!L7<>"",'Linfit Worksheet'!K7,""),"") | E34: =IF('Linfit Worksheet'!K7<>"",IF('Linfit Worksheet'!L7<>"",'Linfit Worksheet'!L7,""),"") | H34: =IF('Linfit Worksheet'!K7<>"",IF('Linfit Worksheet'!L7<>"",'Linfit Worksheet'!N7,""),"")
B35: =IF('Linfit Worksheet'!K8<>"",IF('Linfit Worksheet'!L8<>"",'Linfit Worksheet'!K8,""),"") | E35: =IF('Linfit Worksheet'!K8<>"",IF('Linfit Worksheet'!L8<>"",'Linfit Worksheet'!L8,""),"") | H35: =IF('Linfit Worksheet'!K8<>"",IF('Linfit Worksheet'!L8<>"",'Linfit Worksheet'!N8,""),"")
B36: =IF('Linfit Worksheet'!K9<>"",IF('Linfit Worksheet'!L9<>"",'Linfit Worksheet'!K9,""),"") | E36: =IF('Linfit Worksheet'!K9<>"",IF('Linfit Worksheet'!L9<>"",'Linfit Worksheet'!L9,""),"") | H36: =IF('Linfit Worksheet'!K9<>"",IF('Linfit Worksheet'!L9<>"",'Linfit Worksheet'!N9,""),"") | L36: Customer
B37: =IF('Linfit Worksheet'!K10<>"",IF('Linfit Worksheet'!L10<>"",'Linfit Worksheet'!K10,""),"") | E37: =IF('Linfit Worksheet'!K10<>"",IF('Linfit Worksheet'!L10<>"",'Linfit Worksheet'!L10,""),"") | H37: =IF('Linfit Worksheet'!K10<>"",IF('Linfit Worksheet'!L10<>"",'Linfit Worksheet'!N10,""),"")
B38: =IF('Linfit Worksheet'!K11<>"",IF('Linfit Worksheet'!L11<>"",'Linfit Worksheet'!K11,""),"") | E38: =IF('Linfit Worksheet'!K11<>"",IF('Linfit Worksheet'!L11<>"",'Linfit Worksheet'!L11,""),"") | H38: =IF('Linfit Worksheet'!K11<>"",IF('Linfit Worksheet'!L11<>"",'Linfit Worksheet'!N11,""),"")
B39: =IF('Linfit Worksheet'!K12<>"",IF('Linfit Worksheet'!L12<>"",'Linfit Worksheet'!K12,""),"") | E39: =IF('Linfit Worksheet'!K12<>"",IF('Linfit Worksheet'!L12<>"",'Linfit Worksheet'!L12,""),"") | H39: =IF('Linfit Worksheet'!K12<>"",IF('Linfit Worksheet'!L12<>"",'Linfit Worksheet'!N12,""),"")
B40: =IF('Linfit Worksheet'!K13<>"",IF('Linfit Worksheet'!L13<>"",'Linfit Worksheet'!K13,""),"") | E40: =IF('Linfit Worksheet'!K13<>"",IF('Linfit Worksheet'!L13<>"",'Linfit Worksheet'!L13,""),"") | H40: =IF('Linfit Worksheet'!K13<>"",IF('Linfit Worksheet'!L13<>"",'Linfit Worksheet'!N13,""),"")
B41: =IF('Linfit Worksheet'!K14<>"",IF('Linfit Worksheet'!L14<>"",'Linfit Worksheet'!K14,""),"") | E41: =IF('Linfit Worksheet'!K14<>"",IF('Linfit Worksheet'!L14<>"",'Linfit Worksheet'!L14,""),"") | H41: =IF('Linfit Worksheet'!K14<>"",IF('Linfit Worksheet'!L14<>"",'Linfit Worksheet'!N14,""),"") | L41: User Notes
B42: =IF('Linfit Worksheet'!K15<>"",IF('Linfit Worksheet'!L15<>"",'Linfit Worksheet'!K15,""),"") | E42: =IF('Linfit Worksheet'!K15<>"",IF('Linfit Worksheet'!L15<>"",'Linfit Worksheet'!L15,""),"") | H42: =IF('Linfit Worksheet'!K15<>"",IF('Linfit Worksheet'!L15<>"",'Linfit Worksheet'!N15,""),"")
B43: =IF('Linfit Worksheet'!K16<>"",IF('Linfit Worksheet'!L16<>"",'Linfit Worksheet'!K16,""),"") | E43: =IF('Linfit Worksheet'!K16<>"",IF('Linfit Worksheet'!L16<>"",'Linfit Worksheet'!L16,""),"") | H43: =IF('Linfit Worksheet'!K16<>"",IF('Linfit Worksheet'!L16<>"",'Linfit Worksheet'!N16,""),"")
B44: =IF('Linfit Worksheet'!K17<>"",IF('Linfit Worksheet'!L17<>"",'Linfit Worksheet'!K17,""),"") | E44: =IF('Linfit Worksheet'!K17<>"",IF('Linfit Worksheet'!L17<>"",'Linfit Worksheet'!L17,""),"") | H44: =IF('Linfit Worksheet'!K17<>"",IF('Linfit Worksheet'!L17<>"",'Linfit Worksheet'!N17,""),"")
B45: =IF('Linfit Worksheet'!K18<>"",IF('Linfit Worksheet'!L18<>"",'Linfit Worksheet'!K18,""),"") | E45: =IF('Linfit Worksheet'!K18<>"",IF('Linfit Worksheet'!L18<>"",'Linfit Worksheet'!L18,""),"") | H45: =IF('Linfit Worksheet'!K18<>"",IF('Linfit Worksheet'!L18<>"",'Linfit Worksheet'!N18,""),"")
B46: =IF('Linfit Worksheet'!K19<>"",IF('Linfit Worksheet'!L19<>"",'Linfit Worksheet'!K19,""),"") | E46: =IF('Linfit Worksheet'!K19<>"",IF('Linfit Worksheet'!L19<>"",'Linfit Worksheet'!L19,""),"") | H46: =IF('Linfit Worksheet'!K19<>"",IF('Linfit Worksheet'!L19<>"",'Linfit Worksheet'!N19,""),"") | L46: Unit Condition | U46: Lab Conditions
B47: =IF('Linfit Worksheet'!K20<>"",IF('Linfit Worksheet'!L20<>"",'Linfit Worksheet'!K20,""),"") | E47: =IF('Linfit Worksheet'!K20<>"",IF('Linfit Worksheet'!L20<>"",'Linfit Worksheet'!L20,""),"") | H47: =IF('Linfit Worksheet'!K20<>"",IF('Linfit Worksheet'!L20<>"",'Linfit Worksheet'!N20,""),"") | L47: As Found: | U47: Temperature: | AA47: °C
B48: =IF('Linfit Worksheet'!K21<>"",IF('Linfit Worksheet'!L21<>"",'Linfit Worksheet'!K21,""),"") | E48: =IF('Linfit Worksheet'!K21<>"",IF('Linfit Worksheet'!L21<>"",'Linfit Worksheet'!L21,""),"") | H48: =IF('Linfit Worksheet'!K21<>"",IF('Linfit Worksheet'!L21<>"",'Linfit Worksheet'!N21,""),"") | L48: As Left: | U48: Humidity: | AA48: %
B49: =IF('Linfit Worksheet'!K22<>"",IF('Linfit Worksheet'!L22<>"",'Linfit Worksheet'!K22,""),"") | E49: =IF('Linfit Worksheet'!K22<>"",IF('Linfit Worksheet'!L22<>"",'Linfit Worksheet'!L22,""),"") | H49: =IF('Linfit Worksheet'!K22<>"",IF('Linfit Worksheet'!L22<>"",'Linfit Worksheet'!N22,""),"")
B50: =IF('Linfit Worksheet'!K23<>"",IF('Linfit Worksheet'!L23<>"",'Linfit Worksheet'!K23,""),"") | E50: =IF('Linfit Worksheet'!K23<>"",IF('Linfit Worksheet'!L23<>"",'Linfit Worksheet'!L23,""),"") | H50: =IF('Linfit Worksheet'!K23<>"",IF('Linfit Worksheet'!L23<>"",'Linfit Worksheet'!N23,""),"")
B51: =IF('Linfit Worksheet'!K24<>"",IF('Linfit Worksheet'!L24<>"",'Linfit Worksheet'!K24,""),"") | E51: =IF('Linfit Worksheet'!K24<>"",IF('Linfit Worksheet'!L24<>"",'Linfit Worksheet'!L24,""),"") | H51: =IF('Linfit Worksheet'!K24<>"",IF('Linfit Worksheet'!L24<>"",'Linfit Worksheet'!N24,""),"") | L51: Approval Information
B52: =IF('Linfit Worksheet'!K25<>"",IF('Linfit Worksheet'!L25<>"",'Linfit Worksheet'!K25,""),"") | E52: =IF('Linfit Worksheet'!K25<>"",IF('Linfit Worksheet'!L25<>"",'Linfit Worksheet'!L25,""),"") | H52: =IF('Linfit Worksheet'!K25<>"",IF('Linfit Worksheet'!L25<>"",'Linfit Worksheet'!N25,""),"") | L52: Technician: | U52: Calibration Date:
B53: =IF('Linfit Worksheet'!K26<>"",IF('Linfit Worksheet'!L26<>"",'Linfit Worksheet'!K26,""),"") | E53: =IF('Linfit Worksheet'!K26<>"",IF('Linfit Worksheet'!L26<>"",'Linfit Worksheet'!L26,""),"") | H53: =IF('Linfit Worksheet'!K26<>"",IF('Linfit Worksheet'!L26<>"",'Linfit Worksheet'!N26,""),"") | L53: Approval: | U53: Due Date:
B54: =IF('Linfit Worksheet'!K27<>"",IF('Linfit Worksheet'!L27<>"",'Linfit Worksheet'!K27,""),"") | E54: =IF('Linfit Worksheet'!K27<>"",IF('Linfit Worksheet'!L27<>"",'Linfit Worksheet'!L27,""),"") | H54: =IF('Linfit Worksheet'!K27<>"",IF('Linfit Worksheet'!L27<>"",'Linfit Worksheet'!N27,""),"")

Sheet FRRaw
M4: 0 | N4: 0 | O4: 0 | P4: 0 | Q4: 0 | R4: 0 | S4: 0 | T4: 0 | U4: 0 | V4: 0 | W4: 0
I12: FALSE

Sheet LINRaw

Sheet Vib Analyzer Cert
A2: ~ Vibration Analyzer Certification ~
B4: Analyzer/Meter Information | E4: Analyzer Settings | J4: Frequency Response Test
B5: Manufacturer: | C5: =IF('Vib Analyzer Data'!C5="","",'Vib Analyzer Data'!C5) | E5: Analyzer mode: | H5: =IF('Vib Analyzer Data'!H5="","",LOOKUP('Vib Analyzer Data'!H5,RouteRaw!U3:V6)) | L5: Test Amplitude: | M5: 1
B6: MN: | C6: =IF('Vib Analyzer Data'!C6="","",'Vib Analyzer Data'!C6) | E6: Frequency Max: | H6: =IF('Vib Analyzer Data'!H6="","",'Vib Analyzer Data'!H6) | L6: Amplitude Unit: | M6: mm/s pk
B7: SN: | C7: =IF('Vib Analyzer Data'!C7="","",'Vib Analyzer Data'!C7) | E7: Min: | H7: =IF('Vib Analyzer Data'!H7="","",'Vib Analyzer Data'!H7) | L7: Frequency Unit: | M7: Hz
B8: Cal Tech: | C8: =IF('Vib Analyzer Data'!C8="","",'Vib Analyzer Data'!C8) | E8: Unit: | H8: =IF('Vib Analyzer Data'!H8="","",LOOKUP('Vib Analyzer Data'!H8,RouteRaw!K3:L4))
B9: Cal date: | C9: =IF('Vib Analyzer Data'!C9="","",'Vib Analyzer Data'!C9) | E9: # of Line: | H9: =IF('Vib Analyzer Data'!H9="","",'Vib Analyzer Data'!H9)
B10: Cal due: | C10: =IF('Vib Analyzer Data'!C10="","",'Vib Analyzer Data'!C10) | E10: Averaging Points: | H10: =IF('Vib Analyzer Data'!H10="","",'Vib Analyzer Data'!H10)
E11: Window Type: | H11: =IF('Vib Analyzer Data'!H11="","",LOOKUP('Vib Analyzer Data'!H11,RouteRaw!G3:H6))
G12: Analyzer Sensor Input Sensitivity: | H12: =IF('Vib Analyzer Data'!H12="","",'Vib Analyzer Data'!H12) | I12: =IF('Vib Analyzer Data'!H13="","",LOOKUP('Vib Analyzer Data'!H13,RouteRaw!I3:J4))
B13: Test Equipment
B14: Description | C14: MN | D14: SN | F14: Cal. Date | H14: Sensitivity @ 100 Hz | J14: % Tolerance | L14: % Deviation
B15: PVC | C15: =IF('Vib Analyzer Data'!C16="","",'Vib Analyzer Data'!C16) | D15: =IF('Vib Analyzer Data'!D16:E16="","",'Vib Analyzer Data'!D16:E16) | F15: =IF('Vib Analyzer Data'!F16="","",'Vib Analyzer Data'!F16) | H15: =IF('Vib Analyzer Data'!G16="","",'Vib Analyzer Data'!G16) | I15: =IF('Vib Analyzer Data'!H16="","",'Vib Analyzer Data'!H16) | J15: =IF('Vib Analyzer Data'!K16="","",'Vib Analyzer Data'!K16) | L15: =IF('Vib Analyzer Data'!L16="","",'Vib Analyzer Data'!L16)
B16: Sensor | C16: =IF('Vib Analyzer Data'!C17="","",'Vib Analyzer Data'!C17) | D16: =IF('Vib Analyzer Data'!D17:E17="","",'Vib Analyzer Data'!D17:E17) | F16: =IF('Vib Analyzer Data'!F17="","",'Vib Analyzer Data'!F17) | H16: =IF('Vib Analyzer Data'!G17="","",'Vib Analyzer Data'!G17) | I16: =IF('Vib Analyzer Data'!H17="","",'Vib Analyzer Data'!H17) | J16: =IF('Vib Analyzer Data'!K17="","",'Vib Analyzer Data'!K17) | L16: =IF('Vib Analyzer Data'!L17="","",'Vib Analyzer Data'!L17)
B17: DMM | C17: =IF('Vib Analyzer Data'!C18="","",'Vib Analyzer Data'!C18) | D17: =IF('Vib Analyzer Data'!D18:E18="","",'Vib Analyzer Data'!D18:E18) | F17: =IF('Vib Analyzer Data'!F18="","",'Vib Analyzer Data'!F18)
B32: Data Table | G32: Customer:
B33: ="Input" & CHAR(10) &" (" & M7 & ")" | C33: ="Measured" & CHAR(10) &"(" & M7 & ")" | D33: % Deviation | G33: WearCheck RS
B34: 50 | C34: 50 | D34: =IF(OR(B34="",C34=""),"",(C34/B34-1)*100)
B35: 50 | C35: 50 | D35: =IF(OR(B35="",C35=""),"",(C35/B35-1)*100)
B36: 50 | C36: 50 | D36: =IF(OR(B36="",C36=""),"",(C36/B36-1)*100)
B37: 50 | C37: 50 | D37: =IF(OR(B37="",C37=""),"",(C37/B37-1)*100)
B38: 50 | C38: 50 | D38: =IF(OR(B38="",C38=""),"",(C38/B38-1)*100)
B39: 50 | C39: 50 | D39: =IF(OR(B39="",C39=""),"",(C39/B39-1)*100)
B40: 50 | C40: 50 | D40: =IF(OR(B40="",C40=""),"",(C40/B40-1)*100) | G40: Note:
D41: =IF(OR(B41="",C41=""),"",(C41/B41-1)*100) | G41: Traceable to NIST and PTB. Piezoelectric sensor sensitivity tested by back-to-back comparison per ISO 16063-21. This certificate may not be reproduced except in full, without written permission.
B42: 10 | C42: 10 | D42: =IF(OR(B42="",C42=""),"",(C42/B42-1)*100)
B43: 20 | C43: 20 | D43: =IF(OR(B43="",C43=""),"",(C43/B43-1)*100)
B44: 30 | C44: 30 | D44: =IF(OR(B44="",C44=""),"",(C44/B44-1)*100)
B45: 50 | C45: 50 | D45: =IF(OR(B45="",C45=""),"",(C45/B45-1)*100)
B46: 60 | C46: 60 | D46: =IF(OR(B46="",C46=""),"",(C46/B46-1)*100)
B47: 95 | C47: 95 | D47: =IF(OR(B47="",C47=""),"",(C47/B47-1)*100)
D48: =IF(OR(B48="",C48=""),"",(C48/B48-1)*100)

Sheet VersionInfo
A1: Current Report Workbook Version: | D1: ='Linfit Worksheet'!L29
A2: Version | B2: Changes
A3: 2.0.2 | B3: Introduced Version Log
A5: 2.0.3 | B5: Edited the Route Creator sheet. The decimal place of the amplitude value is now limited based on the selected amplitude unit.
A8: 3.0.0 | B8: In LINData: unlocked H12 and created a drop down menu for acceleration, velocity, and displacement. Modified H13 and created a linked list for the amplitude, velocity and displacement options available on the PVC. Modified I13 and created a drop down list for Volts and mA. Got rid of line 14 (was called "starting point"). Changed the name of table in G10 to "Static Proximity Probe/4-20 mA Vibration Sensor Calibration Data Table" (did not record original name). In FRData: Added checkbox at top right to allow the inline charge amp sensitivity to be displayed. Added the charge amp sensitivity text box. The charge amp sensitivity is now displayed on the Cal Cert.
A16: 3.0.1 | B16: Edited FRData and FRRaw to update the sensitivity displayed in FRData to show mV/pC when "Create Calibration Certificate in pC/g" to pC/g…
A22: 3.0.3 | B22: Fixed MRS PV note on CPM vs Hz
A28: 3.0.4 | B28: Fixed all MRS PV notes, set all worksheets top start in the same cell when activating worksheet, set all worksheets to automatically lock when activated
A34: 3.0.8 | B34: Prompt users to save Calibration route file in ":\CalRecords_PVC\Calibrtion_Route\"
A36: 3.0.9 | B36: Check for illegal character in Route Name or Sensor MN
B37: Replace comma decimal separator to point separator
B38: Fix graphing display on SLinCert
A40: 3.1.0 | B40: Added charge mode sensor support to the Route Creator tab.
A41: 3.2.0 | B41: Added ISO route creator and support for changes in 6.0 route
A42: 3.2.1 | B42: Fixed using comma as the seperator for route creator
A43: 3.2.2 | B43: Fixed data point range in Save_Route_File routine of Generate_CalRoute module (fixed bug where only 28 points were written instead of all 30)
A44: 3.2.3 | B44: Updated logo
A45: 3.2.4 | B45: Removed "Load Test Route" button from Vib Analyzer Data tab & fixed VB error

Sheet RouteRaw
B1: Frequency Units | C1: Sensor Type | D1: Amplitude Units | E1: filenames | H1: Analyzer window
A2: 1 | B2: Hertz | C2: ICP | E2: pvc_route
A3: 2 | B3: CPM | C3: Voltage | D3: g pk | E3: pvc_route2 | G3: 1 | H3: Hanning | I3: 1 | J3: mV/EU | K3: 1 | L3: Hz | N3: 1 | O3: g pk | P3: 1 | R3: Hertz | S3: 1 | U3: 1 | V3: Spectra
C4: Modulated Current | D4: g RMS | E4: pvc_route3 | G4: 2 | H4: Hamming | I4: 2 | J4: V/EU | K4: 2 | L4: CPM | N4: 2 | O4: g RMS | P4: 2 | R4: CPM | S4: 2 | U4: 2 | V4: Overall
C5: Charge | D5: in/s pk | G5: 3 | H5: Flattop | N5: 3 | O5: in/s pk | P5: 3 | U5: 3 | V5: Time waveform
C6: PR | D6: in/s RMS | G6: 4 | H6: Uniform | N6: 4 | O6: in/s RMS | P6: 4
D7: mil p-p | N7: 5 | O7: mil p-p | P7: 5
D8: m/s2 pk | N8: 6 | O8: m/s2 pk | P8: 6
D9: m/s2 RMS | N9: 7 | O9: m/s2 RMS | P9: 7
D10: mm/s pk | N10: 8 | O10: mm/s pk | P10: 8
D11: mm/s RMS | N11: 9 | O11: mm/s RMS | P11: 9
D12: um p-p | N12: 10 | O12: um p-p | P12: 10
A17: Linearity Test
C18: Test Frequency: | D18: =IF('Vib Analyzer Data'!K25="","N/A",'Vib Analyzer Data'!K25)
C19: Frequency Unit: | D19: =IF('Vib Analyzer Data'!K26="","",LOOKUP('Vib Analyzer Data'!K26,RouteRaw!K3:L4))
C20: Amplitude Unit: | D20: =IF('Vib Analyzer Data'!K29="","",LOOKUP('Vib Analyzer Data'!K29,RouteRaw!N3:O12))
C21: Abs. Max Deviation (%): | D21: =MAX('Vib Analyzer Data'!G26:G40,ABS(MIN(('Vib Analyzer Data'!G26:G40))))
A22: Frequency Response Test
C23: Test Amplitude: | D23: =IF('Vib Analyzer Data'!K28="","N/A",'Vib Analyzer Data'!K28)
C24: Amplitude Unit: | D24: =IF('Vib Analyzer Data'!K29="","",LOOKUP('Vib Analyzer Data'!K29,RouteRaw!N3:O12))
C25: Frequency Unit: | D25: =IF('Vib Analyzer Data'!K26="","",LOOKUP('Vib Analyzer Data'!K26,RouteRaw!K3:L4))
D26: =IF('Vib Analyzer Data'!K27="","",LOOKUP('Vib Analyzer Data'!K27,RouteRaw!K4:L5))

Sheet Linfit Worksheet
A1: PLEASE DO NOT DELETE THIS TABLE (USED FOR LINEARITY CALCULATION) | K1: Test Level | M1: Linfit | N1: Linearity | V1: Acceleration | W1: g pk | X1: in/s pk | Y1: mil p-p | Z1: V | AA1: g pk | AB1: g | AC1: =LINData!H13 | AD1: =LOOKUP('Linfit Worksheet'!AC1,VibeUnits,SensUnits) | AE1: Hard Limit | AF1: 6.0 or later
A2: For Dynamic Linearity | C2: test level | D2: mVpk | E2: linfit (mVpk) | F2: linearity %FS | G2: Absolute | H2: zero line | J2: For Static Linearity | K2: =LINData!H13 | L2: =LINData!I13 | M2: =L2 | N2: % | V2: Velocity | W2: g RMS | X2: in/s RMS | Y2: mil | Z2: mV | AA2: g RMS | AB2: g | AC2: =LINData!B13 | AD2: =IF(AC2="","",LOOKUP('Linfit Worksheet'!AC2,VibeUnits,SensUnits)) | AE2: ISO | AF2: 5.3 or earlier
C3: 0 | E3: 0 | H3: 0 | J3: SLOPE | K3: =IF(Q7<>"",Q7,"") | L3: =IF(R7<>"",R7,"") | M3: =IF(S7<>"",S7,"") | N3: =T7 | Q3: =IF(K3<>"",ABS(L3/M3-1),"") | V3: Displacement | W3: m/s2 pk | X3: mm/s pk | Y3: um p-p | Z3: mA | AA3: in/s pk | AB3: in/s
A4: Slope: | B4: =LINEST(D4:D4,C4:C4,TRUE) | C4: =IF(LINData!B14>0,IF(LINData!C14>0,LINData!B14,""),"") | D4: =IF(LINData!B14>0,IF(LINData!C14>0,LINData!C14,""),"") | E4: =IF(C4<>"",IF(D4<>"",$B$9*C4+$B$10,""),"") | F4: =IF(C4<>"",IF(D4<>"",(D4-E4)/$B$5*100,""),"") | G4: =IF(C4<>"",IF(D4<>"",ABS(F4),""),"") | H4: =IF(C4<>"",IF(D4<>"",0,""),"") | J4: =INDEX(LINEST(LINData!I14:I15,LINData!H14:H15,TRUE),1,1) | K4: =IF(Q8<>"",Q8,"") | L4: =IF(R8<>"",R8,"") | M4: =IF(S8<>"",S8,"") | N4: =T8 | W4: m/s2 RMS | X4: mm/s RMS | Y4: um | Z4: uA | AA4: in/s RMS | AB4: in/s
A5: FS linfit (mVpk) | C5: =IF(LINData!B15>0,IF(LINData!C15>0,LINData!B15,""),"") | D5: =IF(LINData!B15>0,IF(LINData!C15>0,LINData!C15,""),"") | E5: =IF(C5<>"",IF(D5<>"",$B$9*C5+$B$10,""),"") | F5: =IF(C5<>"",IF(D5<>"",(D5-E5)/$B$5*100,""),"") | G5: =IF(C5<>"",IF(D5<>"",ABS(F5),""),"") | H5: =IF(C5<>"",IF(D5<>"",0,""),"") | J5: INTERCEPT | K5: =IF(Q9<>"",Q9,"") | L5: =IF(R9<>"",R9,"") | M5: =IF(S9<>"",S9,"") | N5: =T9 | Q5: Test Level | S5: Linfit | T5: Linearity | AA5: m/s2 pk | AB5: m/s2
A6: max linearity | B6: =MAX(G4:G13) | C6: =IF(LINData!B16>0,IF(LINData!C16>0,LINData!B16,""),"") | D6: =IF(LINData!B16>0,IF(LINData!C16>0,LINData!C16,""),"") | E6: =IF(C6<>"",IF(D6<>"",$B$9*C6+$B$10,""),"") | F6: =IF(C6<>"",IF(D6<>"",(D6-E6)/$B$5*100,""),"") | G6: =IF(C6<>"",IF(D6<>"",ABS(F6),""),"") | H6: =IF(C6<>"",IF(D6<>"",0,""),"") | J6: =INDEX(LINEST(LINData!I14:I15,LINData!H14:H15,TRUE),1,2) | K6: =IF(Q10<>"",Q10,"") | L6: =IF(R10<>"",R10,"") | M6: =IF(S10<>"",S10,"") | N6: =T10 | P6: Point | Q6: =LINData!H13 | R6: =LINData!I13 | S6: =L2 | T6: % | AA6: m/s2 RMS | AB6: m/s2
A7: ="Sensitivity ("&LINData!B11&")" | B7: =$B$4 | C7: =IF(LINData!B17>0,IF(LINData!C17>0,LINData!B17,""),"") | D7: =IF(LINData!B17>0,IF(LINData!C17>0,LINData!C17,""),"") | E7: =IF(C7<>"",IF(D7<>"",$B$9*C7+$B$10,""),"") | F7: =IF(C7<>"",IF(D7<>"",(D7-E7)/$B$5*100,""),"") | G7: =IF(C7<>"",IF(D7<>"",ABS(F7),""),"") | H7: =IF(C7<>"",IF(D7<>"",0,""),"") | J7: ymax | K7: =IF(Q11<>"",Q11,"") | L7: =IF(R11<>"",R11,"") | M7: =IF(S11<>"",S11,"") | N7: =T11 | P7: Reference | Q7: =IF(LINData!H14<>"",LINData!H14,"") | R7: =IF(LINData!I14<>"",LINData!I14,"") | S7: =IF(Q7<>"",Q7*$J$4+$J$6,"") | T7: =IF(Q7<>"",ABS(R7/S7-1),"") | AA7: mil p-p | AB7: mil
C8: =IF(LINData!B18>0,IF(LINData!C18>0,LINData!B18,""),"") | D8: =IF(LINData!B18>0,IF(LINData!C18>0,LINData!C18,""),"") | E8: =IF(C8<>"",IF(D8<>"",$B$9*C8+$B$10,""),"") | F8: =IF(C8<>"",IF(D8<>"",(D8-E8)/$B$5*100,""),"") | G8: =IF(C8<>"",IF(D8<>"",ABS(F8),""),"") | H8: =IF(C8<>"",IF(D8<>"",0,""),"") | J8: =MAX(L3:L27) | K8: =IF(Q12<>"",Q12,"") | L8: =IF(R12<>"",R12,"") | M8: =IF(S12<>"",S12,"") | N8: =T12 | P8: 1 | Q8: =IF(LINData!H15<>"",LINData!H15,"") | R8: =IF(LINData!I15<>"",LINData!I15,"") | S8: =IF(Q8<>"",Q8*$J$4+$J$6,"") | T8: =IF(Q8<>"",ABS(R8/S8-1),"") | AA8: mm/s pk | AB8: mm/s
A9: Slope: | B9: =INDEX(LINEST(D4:D4,C4:C4,TRUE),1,1) | C9: =IF(LINData!B19>0,IF(LINData!C19>0,LINData!B19,""),"") | D9: =IF(LINData!B19>0,IF(LINData!C19>0,LINData!C19,""),"") | E9: =IF(C9<>"",IF(D9<>"",$B$9*C9+$B$10,""),"") | F9: =IF(C9<>"",IF(D9<>"",(D9-E9)/$B$5*100,""),"") | G9: =IF(C9<>"",IF(D9<>"",ABS(F9),""),"") | H9: =IF(C9<>"",IF(D9<>"",0,""),"") | J9: xmax | K9: =IF(Q13<>"",Q13,"") | L9: =IF(R13<>"",R13,"") | M9: =IF(S13<>"",S13,"") | N9: =T13 | P9: 2 | Q9: =IF(LINData!H16<>"",LINData!H16,"") | R9: =IF(LINData!I16<>"",LINData!I16,"") | S9: =IF(Q9<>"",Q9*$J$4+$J$6,"") | T9: =IF(Q9<>"",ABS(R9/S9-1),"") | AA9: mm/s RMS | AB9: mm/s
A10: Y-Intercept | B10: =INDEX(LINEST(D4:D4,C4:C4,TRUE),1,2) | C10: =IF(LINData!B20>0,IF(LINData!C20>0,LINData!B20,""),"") | D10: =IF(LINData!B20>0,IF(LINData!C20>0,LINData!C20,""),"") | E10: =IF(C10<>"",IF(D10<>"",$B$9*C10+$B$10,""),"") | F10: =IF(C10<>"",IF(D10<>"",(D10-E10)/$B$5*100,""),"") | G10: =IF(C10<>"",IF(D10<>"",ABS(F10),""),"") | H10: =IF(C10<>"",IF(D10<>"",0,""),"") | J10: =MAX(K3:K27) | K10: =IF(Q14<>"",Q14,"") | L10: =IF(R14<>"",R14,"") | M10: =IF(S14<>"",S14,"") | N10: =T14 | P10: 3 | Q10: =IF(LINData!H17<>"",LINData!H17,"") | R10: =IF(LINData!I17<>"",LINData!I17,"") | S10: =IF(Q10<>"",Q10*$J$4+$J$6,"") | T10: =IF(Q10<>"",ABS(R10/S10-1),"") | AA10: um p-p | AB10: um
A11: xMax | B11: =MAX(C3:C33) | C11: =IF(LINData!B21>0,IF(LINData!C21>0,LINData!B21,""),"") | D11: =IF(LINData!B21>0,IF(LINData!C21>0,LINData!C21,""),"") | E11: =IF(C11<>"",IF(D11<>"",$B$9*C11+$B$10,""),"") | F11: =IF(C11<>"",IF(D11<>"",(D11-E11)/$B$5*100,""),"") | G11: =IF(C11<>"",IF(D11<>"",ABS(F11),""),"") | H11: =IF(C11<>"",IF(D11<>"",0,""),"") | J11: sensitivity | K11: =IF(Q15<>"",Q15,"") | L11: =IF(R15<>"",R15,"") | M11: =IF(S15<>"",S15,"") | N11: =T15 | P11: 4 | Q11: =IF(LINData!H18<>"",LINData!H18,"") | R11: =IF(LINData!I18<>"",LINData!I18,"") | S11: =IF(Q11<>"",Q11*$J$4+$J$6,"") | T11: =IF(Q11<>"",ABS(R11/S11-1),"")
A12: yMax | B12: =MAX(D4:E33) | C12: =IF(LINData!B22>0,IF(LINData!C22>0,LINData!B22,""),"") | D12: =IF(LINData!B22>0,IF(LINData!C22>0,LINData!C22,""),"") | E12: =IF(C12<>"",IF(D12<>"",$B$9*C12+$B$10,""),"") | F12: =IF(C12<>"",IF(D12<>"",(D12-E12)/$B$5*100,""),"") | G12: =IF(C12<>"",IF(D12<>"",ABS(F12),""),"") | H12: =IF(C12<>"",IF(D12<>"",0,""),"") | J12: =IF(Q7<>"",J4,"") | K12: =IF(Q16<>"",Q16,"") | L12: =IF(R16<>"",R16,"") | M12: =IF(S16<>"",S16,"") | N12: =T16 | P12: 5 | Q12: =IF(LINData!H19<>"",LINData!H19,"") | R12: =IF(LINData!I19<>"",LINData!I19,"") | S12: =IF(Q12<>"",Q12*$J$4+$J$6,"") | T12: =IF(Q12<>"",ABS(R12/S12-1),"") | AD12: FALSE
A13: xMin | B13: =MIN(C4:C33) | C13: =IF(LINData!B23>0,IF(LINData!C23>0,LINData!B23,""),"") | D13: =IF(LINData!B23>0,IF(LINData!C23>0,LINData!C23,""),"") | E13: =IF(C13<>"",IF(D13<>"",$B$9*C13+$B$10,""),"") | F13: =IF(C13<>"",IF(D13<>"",(D13-E13)/$B$5*100,""),"") | G13: =IF(C13<>"",IF(D13<>"",ABS(F13),""),"") | H13: =IF(C13<>"",IF(D13<>"",0,""),"") | K13: =IF(Q17<>"",Q17,"") | L13: =IF(R17<>"",R17,"") | M13: =IF(S17<>"",S17,"") | N13: =T17 | P13: 6 | Q13: =IF(LINData!H20<>"",LINData!H20,"") | R13: =IF(LINData!I20<>"",LINData!I20,"") | S13: =IF(Q13<>"",Q13*$J$4+$J$6,"") | T13: =IF(Q13<>"",ABS(R13/S13-1),"")
C14: =IF(LINData!B24>0,IF(LINData!C24>0,LINData!B24,""),"") | D14: =IF(LINData!B24>0,IF(LINData!C24>0,LINData!C24,""),"") | E14: =IF(C14<>"",IF(D14<>"",$B$9*C14+$B$10,""),"") | F14: =IF(C14<>"",IF(D14<>"",(D14-E14)/$B$5*100,""),"") | G14: =IF(C14<>"",IF(D14<>"",ABS(F14),""),"") | H14: =IF(C14<>"",IF(D14<>"",0,""),"") | K14: =IF(Q18<>"",Q18,"") | L14: =IF(R18<>"",R18,"") | M14: =IF(S18<>"",S18,"") | N14: =T18 | P14: 7 | Q14: =IF(LINData!H21<>"",LINData!H21,"") | R14: =IF(LINData!I21<>"",LINData!I21,"") | S14: =IF(Q14<>"",Q14*$J$4+$J$6,"") | T14: =IF(Q14<>"",ABS(R14/S14-1),"")
C15: =IF(LINData!B25>0,IF(LINData!C25>0,LINData!B25,""),"") | D15: =IF(LINData!B25>0,IF(LINData!C25>0,LINData!C25,""),"") | E15: =IF(C15<>"",IF(D15<>"",$B$9*C15+$B$10,""),"") | F15: =IF(C15<>"",IF(D15<>"",(D15-E15)/$B$5*100,""),"") | G15: =IF(C15<>"",IF(D15<>"",ABS(F15),""),"") | H15: =IF(C15<>"",IF(D15<>"",0,""),"") | K15: =IF(Q19<>"",Q19,"") | L15: =IF(R19<>"",R19,"") | M15: =IF(S19<>"",S19,"") | N15: =T19 | P15: 8 | Q15: =IF(LINData!H22<>"",LINData!H22,"") | R15: =IF(LINData!I22<>"",LINData!I22,"") | S15: =IF(Q15<>"",Q15*$J$4+$J$6,"") | T15: =IF(Q15<>"",ABS(R15/S15-1),"")
C16: =IF(LINData!B26>0,IF(LINData!C26>0,LINData!B26,""),"") | D16: =IF(LINData!B26>0,IF(LINData!C26>0,LINData!C26,""),"") | E16: =IF(C16<>"",IF(D16<>"",$B$9*C16+$B$10,""),"") | F16: =IF(C16<>"",IF(D16<>"",(D16-E16)/$B$5*100,""),"") | G16: =IF(C16<>"",IF(D16<>"",ABS(F16),""),"") | H16: =IF(C16<>"",IF(D16<>"",0,""),"") | K16: =IF(Q20<>"",Q20,"") | L16: =IF(R20<>"",R20,"") | M16: =IF(S20<>"",S20,"") | N16: =T20 | P16: 9 | Q16: =IF(LINData!H23<>"",LINData!H23,"") | R16: =IF(LINData!I23<>"",LINData!I23,"") | S16: =IF(Q16<>"",Q16*$J$4+$J$6,"") | T16: =IF(Q16<>"",ABS(R16/S16-1),"")
C17: =IF(LINData!B27>0,IF(LINData!C27>0,LINData!B27,""),"") | D17: =IF(LINData!B27>0,IF(LINData!C27>0,LINData!C27,""),"") | E17: =IF(C17<>"",IF(D17<>"",$B$9*C17+$B$10,""),"") | F17: =IF(C17<>"",IF(D17<>"",(D17-E17)/$B$5*100,""),"") | G17: =IF(C17<>"",IF(D17<>"",ABS(F17),""),"") | H17: =IF(C17<>"",IF(D17<>"",0,""),"") | K17: =IF(Q21<>"",Q21,"") | L17: =IF(R21<>"",R21,"") | M17: =IF(S21<>"",S21,"") | N17: =T21 | P17: 10 | Q17: =IF(LINData!H24<>"",LINData!H24,"") | R17: =IF(LINData!I24<>"",LINData!I24,"") | S17: =IF(Q17<>"",Q17*$J$4+$J$6,"") | T17: =IF(Q17<>"",ABS(R17/S17-1),"")
C18: =IF(LINData!B28>0,IF(LINData!C28>0,LINData!B28,""),"") | D18: =IF(LINData!B28>0,IF(LINData!C28>0,LINData!C28,""),"") | E18: =IF(C18<>"",IF(D18<>"",$B$9*C18+$B$10,""),"") | F18: =IF(C18<>"",IF(D18<>"",(D18-E18)/$B$5*100,""),"") | G18: =IF(C18<>"",IF(D18<>"",ABS(F18),""),"") | H18: =IF(C18<>"",IF(D18<>"",0,""),"") | K18: =IF(Q22<>"",Q22,"") | L18: =IF(R22<>"",R22,"") | M18: =IF(S22<>"",S22,"") | N18: =T22 | P18: 11 | Q18: =IF(LINData!H25<>"",LINData!H25,"") | R18: =IF(LINData!I25<>"",LINData!I25,"") | S18: =IF(Q18<>"",Q18*$J$4+$J$6,"") | T18: =IF(Q18<>"",ABS(R18/S18-1),"")
C19: =IF(LINData!B29>0,IF(LINData!C29>0,LINData!B29,""),"") | D19: =IF(LINData!B29>0,IF(LINData!C29>0,LINData!C29,""),"") | E19: =IF(C19<>"",IF(D19<>"",$B$9*C19+$B$10,""),"") | F19: =IF(C19<>"",IF(D19<>"",(D19-E19)/$B$5*100,""),"") | G19: =IF(C19<>"",IF(D19<>"",ABS(F19),""),"") | H19: =IF(C19<>"",IF(D19<>"",0,""),"") | K19: =IF(Q23<>"",Q23,"") | L19: =IF(R23<>"",R23,"") | M19: =IF(S23<>"",S23,"") | N19: =T23 | P19: 12 | Q19: =IF(LINData!H26<>"",LINData!H26,"") | R19: =IF(LINData!I26<>"",LINData!I26,"") | S19: =IF(Q19<>"",Q19*$J$4+$J$6,"") | T19: =IF(Q19<>"",ABS(R19/S19-1),"")
C20: =IF(LINData!B30>0,IF(LINData!C30>0,LINData!B30,""),"") | D20: =IF(LINData!B30>0,IF(LINData!C30>0,LINData!C30,""),"") | E20: =IF(C20<>"",IF(D20<>"",$B$9*C20+$B$10,""),"") | F20: =IF(C20<>"",IF(D20<>"",(D20-E20)/$B$5*100,""),"") | G20: =IF(C20<>"",IF(D20<>"",ABS(F20),""),"") | H20: =IF(C20<>"",IF(D20<>"",0,""),"") | K20: =IF(Q24<>"",Q24,"") | L20: =IF(R24<>"",R24,"") | M20: =IF(S24<>"",S24,"") | N20: =T24 | P20: 13 | Q20: =IF(LINData!H27<>"",LINData!H27,"") | R20: =IF(LINData!I27<>"",LINData!I27,"") | S20: =IF(Q20<>"",Q20*$J$4+$J$6,"") | T20: =IF(Q20<>"",ABS(R20/S20-1),"")
C21: =IF(LINData!B31>0,IF(LINData!C31>0,LINData!B31,""),"") | D21: =IF(LINData!B31>0,IF(LINData!C31>0,LINData!C31,""),"") | E21: =IF(C21<>"",IF(D21<>"",$B$9*C21+$B$10,""),"") | F21: =IF(C21<>"",IF(D21<>"",(D21-E21)/$B$5*100,""),"") | G21: =IF(C21<>"",IF(D21<>"",ABS(F21),""),"") | H21: =IF(C21<>"",IF(D21<>"",0,""),"") | K21: =IF(Q25<>"",Q25,"") | L21: =IF(R25<>"",R25,"") | M21: =IF(S25<>"",S25,"") | N21: =T25 | P21: 14 | Q21: =IF(LINData!H28<>"",LINData!H28,"") | R21: =IF(LINData!I28<>"",LINData!I28,"") | S21: =IF(Q21<>"",Q21*$J$4+$J$6,"") | T21: =IF(Q21<>"",ABS(R21/S21-1),"")
C22: =IF(LINData!B32>0,IF(LINData!C32>0,LINData!B32,""),"") | D22: =IF(LINData!B32>0,IF(LINData!C32>0,LINData!C32,""),"") | E22: =IF(C22<>"",IF(D22<>"",$B$9*C22+$B$10,""),"") | F22: =IF(C22<>"",IF(D22<>"",(D22-E22)/$B$5*100,""),"") | G22: =IF(C22<>"",IF(D22<>"",ABS(F22),""),"") | H22: =IF(C22<>"",IF(D22<>"",0,""),"") | K22: =IF(Q26<>"",Q26,"") | L22: =IF(R26<>"",R26,"") | M22: =IF(S26<>"",S26,"") | N22: =T26 | P22: 15 | Q22: =IF(LINData!H29<>"",LINData!H29,"") | R22: =IF(LINData!I29<>"",LINData!I29,"") | S22: =IF(Q22<>"",Q22*$J$4+$J$6,"") | T22: =IF(Q22<>"",ABS(R22/S22-1),"")
C23: =IF(LINData!B33>0,IF(LINData!C33>0,LINData!B33,""),"") | D23: =IF(LINData!B33>0,IF(LINData!C33>0,LINData!C33,""),"") | E23: =IF(C23<>"",IF(D23<>"",$B$9*C23+$B$10,""),"") | F23: =IF(C23<>"",IF(D23<>"",(D23-E23)/$B$5*100,""),"") | G23: =IF(C23<>"",IF(D23<>"",ABS(F23),""),"") | H23: =IF(C23<>"",IF(D23<>"",0,""),"") | K23: =IF(Q27<>"",Q27,"") | L23: =IF(R27<>"",R27,"") | M23: =IF(S27<>"",S27,"") | N23: =T27 | P23: 16 | Q23: =IF(LINData!H30<>"",LINData!H30,"") | R23: =IF(LINData!I30<>"",LINData!I30,"") | S23: =IF(Q23<>"",Q23*$J$4+$J$6,"") | T23: =IF(Q23<>"",ABS(R23/S23-1),"")
C24: =IF(LINData!B34>0,IF(LINData!C34>0,LINData!B34,""),"") | D24: =IF(LINData!B34>0,IF(LINData!C34>0,LINData!C34,""),"") | E24: =IF(C24<>"",IF(D24<>"",$B$9*C24+$B$10,""),"") | F24: =IF(C24<>"",IF(D24<>"",(D24-E24)/$B$5*100,""),"") | G24: =IF(C24<>"",IF(D24<>"",ABS(F24),""),"") | H24: =IF(C24<>"",IF(D24<>"",0,""),"") | K24: =IF(Q28<>"",Q28,"") | L24: =IF(R28<>"",R28,"") | M24: =IF(S28<>"",S28,"") | N24: =T28 | P24: 17 | Q24: =IF(LINData!H31<>"",LINData!H31,"") | R24: =IF(LINData!I31<>"",LINData!I31,"") | S24: =IF(Q24<>"",Q24*$J$4+$J$6,"") | T24: =IF(Q24<>"",ABS(R24/S24-1),"")
C25: =IF(LINData!B35>0,IF(LINData!C35>0,LINData!B35,""),"") | D25: =IF(LINData!B35>0,IF(LINData!C35>0,LINData!C35,""),"") | E25: =IF(C25<>"",IF(D25<>"",$B$9*C25+$B$10,""),"") | F25: =IF(C25<>"",IF(D25<>"",(D25-E25)/$B$5*100,""),"") | G25: =IF(C25<>"",IF(D25<>"",ABS(F25),""),"") | H25: =IF(C25<>"",IF(D25<>"",0,""),"") | K25: =IF(Q29<>"",Q29,"") | L25: =IF(R29<>"",R29,"") | M25: =IF(S29<>"",S29,"") | N25: =T29 | P25: 18 | Q25: =IF(LINData!H32<>"",LINData!H32,"") | R25: =IF(LINData!I32<>"",LINData!I32,"") | S25: =IF(Q25<>"",Q25*$J$4+$J$6,"") | T25: =IF(Q25<>"",ABS(R25/S25-1),"")
... C27: =IF(LINData!B37>0,IF(LINData!C37>0,LINData!B37,""),"") | D27: =IF(LINData!B37>0,IF(LINData!C37>0,LINData!C37,""),"") | E27: =IF(C27<>"",IF(D27<>"",$B$9*C27+$B$10,""),"") | F27: =IF(C27<>"",IF(D27<>"",(D27-E27)/$B$5*100,""),"") | G27: =IF(C27<>"",IF(D27<>"",ABS(F27),""),"") | H27: =IF(C27<>"",IF(D27<>"",0,""),"") | K27: =IF(Q31<>"",Q31,"") | L27: =IF(R31<>"",R31,"") | M27: =IF(S31<>"",S31,"") | N27: =T31 | P27: 20 | Q27: =IF(LINData!H34<>"",LINData!H34,"") | R27: =IF(LINData!I34<>"",LINData!I34,"") | S27: =IF(Q27<>"",Q27*$J$4+$J$6,"") | T27: =IF(Q27<>"",ABS(R27/S27-1),"")
C28: =IF(LINData!B38>0,IF(LINData!C38>0,LINData!B38,""),"") | D28: =IF(LINData!B38>0,IF(LINData!C38>0,LINData!C38,""),"") | E28: =IF(C28<>"",IF(D28<>"",$B$9*C28+$B$10,""),"") | F28: =IF(C28<>"",IF(D28<>"",(D28-E28)/$B$5*100,""),"") | G28: =IF(C28<>"",IF(D28<>"",ABS(F28),""),"") | H28: =IF(C28<>"",IF(D28<>"",0,""),"") | P28: 21 | Q28: =IF(LINData!H35<>"",LINData!H35,"") | R28: =IF(LINData!I35<>"",LINData!I35,"") | S28: =IF(Q28<>"",Q28*$J$4+$J$6,"") | T28: =IF(Q28<>"",ABS(R28/S28-1),"")
